Workbook

Sheet 2026
A1: c];jhj; ngau;……………………….……….. | E1: c];jhj; ngau;……………………….………..
A2: Rl;byf;fk; | B2: khztu; ngau; | C2: ed;dlj;ijg; Gs;sp | E2: Admision No | F2: Name with initial | G2: Full Name | H2: Date of Birth | I2: Age | J2: N.I.C Number | K2: Date of Admision | L2: Father 's Status Alive / Deceased | M2: Father | N2: Grade in madrasa | O2: Class Usthadh | P2: Class Usthadh Contact Number | Q2: Grade in School | R2: Section | S2: Distric | T2: Address | U2: Contact
A3: 243 | B3: AKMAL ABDUL LATHEEF | E3: 243 | F3: A.L.M.AKMAL | G3: ABDUL LATHEEF MUHAMMAD AKMAL | H3: 36875 | I3: =DATEDIF(H3, TODAY(), "Y") & " Y " & DATEDIF(H3, TODAY(), "YM") & " M" -> 25 Y 1 M | J3: 200035003262 | L3: YES | N3: 7 | O3: =VLOOKUP(N3,$A$162:$B$172,2,FALSE) -> ASH-SHAIKH FAYZEEN | P3: =VLOOKUP(N3,$A$162:$C$172,3,FALSE) -> 0775020033 / 0761792209 | R3: SHAREE'AH | S3: KALUTARA | T3: 15/18A, MADAKISSA RD, HORETHUDUWE, KESALWATTA. | U3: 0777705940 / 0755764243
A4: 248 | B4: ISHFAK ILFAN | E4: 248 | F4: M.I.M.ISHFAQ | G4: MUHAMMAD ILFAN MUHAMMAD ISHFAQ | H4: 37316 | I4: =DATEDIF(H4, TODAY(), "Y") & " Y " & DATEDIF(H4, TODAY(), "YM") & " M" -> 23 Y 11 M | J4: 200206103934 | L4: YES | N4: 7 | O4: =VLOOKUP(N4,$A$162:$B$172,2,FALSE) -> ASH-SHAIKH FAYZEEN | P4: =VLOOKUP(N4,$A$162:$C$172,3,FALSE) -> 0775020033 / 0761792209 | R4: SHAREE'AH | S4: KALUTARA | T4: 73/6,TSNAMI HOUSES, DHARGA RD, BERUWELA. | U4: 0769455844 / 0774008535
A5: 250 | B5: FAIZAL ASHRAF | E5: 250 | F5: M.A.M.FAISAL | G5: MUHAMMAD ASHRAF MUHAMMAD FAISAL | H5: 37702 | I5: =DATEDIF(H5, TODAY(), "Y") & " Y " & DATEDIF(H5, TODAY(), "YM") & " M" -> 22 Y 10 M | J5: 200308200369 | L5: NO | M5: Death | N5: 7 | O5: =VLOOKUP(N5,$A$162:$B$172,2,FALSE) -> ASH-SHAIKH FAYZEEN | P5: =VLOOKUP(N5,$A$162:$C$172,3,FALSE) -> 0775020033 / 0761792209 | R5: SHAREE'AH | S5: KALUTARA | T5: 148/40, KADHIYA WATTA RD, WELIPITIYA, DHARGA TOWN. | U5: 0770333163 / 0778620559
A6: 325 | B6: ABDUR RAHMAN RIZWAN | E6: 325 | F6: M.R.ABDUR RAHMAN | G6: MUHAMMAD RIZWAN ABDUR RAHMAN | H6: 37891 | I6: =DATEDIF(H6, TODAY(), "Y") & " Y " & DATEDIF(H6, TODAY(), "YM") & " M" -> 22 Y 4 M | J6: 200327113163 | L6: YES | N6: 7 | O6: =VLOOKUP(N6,$A$162:$B$172,2,FALSE) -> ASH-SHAIKH FAYZEEN | P6: =VLOOKUP(N6,$A$162:$C$172,3,FALSE) -> 0775020033 / 0761792209 | R6: SHAREE'AH | S6: PUTTALAM | T6: HIJRA LANE, PUTHUKUDIERUPPU, BATTULU OYA. | U6: 0717257977 / 0775856331
A7: 331 | B7: ABDULLAH IJAZ | E7: 331 | F7: M.I.ABDULLAH | G7: MUHAMMAD IJAZ ABDULLAH | H7: 38586 | I7: =DATEDIF(H7, TODAY(), "Y") & " Y " & DATEDIF(H7, TODAY(), "YM") & " M" -> 20 Y 5 M | J7: 200522901050 | L7: YES | N7: 4 | O7: =VLOOKUP(N7,$A$162:$B$172,2,FALSE) -> ASH-SHAIKH MUNTHASIR | P7: =VLOOKUP(N7,$A$162:$C$172,3,FALSE) -> 0762663436 / 0755050300 | R7: SHAREE'AH | S7: KALUTARA | T7: 20/7, S,M LANE, WELPITIYA, DARGA TOWN. | U7: 0
A8: 341 | B8: AHAMEDH MAFAIS | E8: 341 | F8: M.M.AHMAD | G8: MMUHAMMAD MAFAIZ AHMAD | H8: 38528 | I8: =DATEDIF(H8, TODAY(), "Y") & " Y " & DATEDIF(H8, TODAY(), "YM") & " M" -> 20 Y 7 M | J8: 200517704065 | L8: YES | N8: 5 | O8: =VLOOKUP(N8,$A$162:$B$172,2,FALSE) -> ASH-SHAIKH HARSAN | P8: =VLOOKUP(N8,$A$162:$C$172,3,FALSE) -> 0774746493 / 0719150788 | R8: SHAREE'AH | S8: KALUTARA | T8: 41,THOTAWATHA, PANADURA. | U8: 772696059
A9: 342 | B9: ILHAM IRFAN | E9: 342 | F9: M.I.M. ILHAM | G9: MUHAMMAD IRFAN MUHAMMAD ILHAM | H9: 38519 | I9: =DATEDIF(H9, TODAY(), "Y") & " Y " & DATEDIF(H9, TODAY(), "YM") & " M" -> 20 Y 7 M | J9: 200516803973 | L9: YES | N9: 6 | O9: =VLOOKUP(N9,$A$162:$B$172,2,FALSE) -> ASH-SHAIKH SHAHEER AHMED | P9: =VLOOKUP(N9,$A$162:$C$172,3,FALSE) -> 757296619 | R9: SHAREE'AH | S9: KALUTARA | T9: 68/4,MARIKAR STREETS, KALUTHARA SOUTH. | U9: 757510962
A10: 345 | B10: AHSAN SHAKIR | E10: 345 | F10: M.S.M.AHSAN | G10: MUHAMMAD SHAKIR MUHAMMAD AHSAN | H10: 38162 | I10: =DATEDIF(H10, TODAY(), "Y") & " Y " & DATEDIF(H10, TODAY(), "YM") & " M" -> 21 Y 7 M | J10: 200417800580 | L10: YES | N10: 6 | O10: =VLOOKUP(N10,$A$162:$B$172,2,FALSE) -> ASH-SHAIKH SHAHEER AHMED | P10: =VLOOKUP(N10,$A$162:$C$172,3,FALSE) -> 757296619 | R10: SHAREE'AH | S10: KALUTARA | T10: 387/1, IBRAHEEM HAJIAR MW, A,BAMUNU MULLA , ATULUGAMA , BANDARA GAMA. | U10: 763433801
A11: 354 | B11: ABDULLAH MUNDHIR | E11: 354 | F11: M.M. ABDULLAH | G11: MUHAMMAD MUNDHIR ABDULLAH | H11: 37944 | I11: =DATEDIF(H11, TODAY(), "Y") & " Y " & DATEDIF(H11, TODAY(), "YM") & " M" -> 22 Y 2 M | J11: 200332413390 | L11: YES | N11: 7 | O11: =VLOOKUP(N11,$A$162:$B$172,2,FALSE) -> ASH-SHAIKH FAYZEEN | P11: =VLOOKUP(N11,$A$162:$C$172,3,FALSE) -> 0775020033 / 0761792209 | R11: SHAREE'AH | S11: KALUTARA | T11: 16, ZAVIYA RD, MAHAGODA, BERUWELA. | U11: 0768822240 / 0778119004
A12: 356 | B12: SAFRAN NALEEM | E12: 356 | F12: N.M.SHAFRAN | G12: NALEEM MUHAMMAD SAFRAN | H12: 37989 | I12: =DATEDIF(H12, TODAY(), "Y") & " Y " & DATEDIF(H12, TODAY(), "YM") & " M" -> 22 Y 1 M | J12: 200500504225 | L12: YES | N12: 5 | O12: =VLOOKUP(N12,$A$162:$B$172,2,FALSE) -> ASH-SHAIKH HARSAN | P12: =VLOOKUP(N12,$A$162:$C$172,3,FALSE) -> 0774746493 / 0719150788 | R12: SHAREE'AH | S12: TRINCOMALEE | T12: 104, KINNIYA, ANNA NAGAR. | U12: 755093414
A13: 363 | B13: IKRAM IRFAN | E13: 363 | F13: M.I.M. IKRAM | G13: MUHAMMAD IRFAN MUHAMMAD IKRAM | H13: 39056 | I13: =DATEDIF(H13, TODAY(), "Y") & " Y " & DATEDIF(H13, TODAY(), "YM") & " M" -> 19 Y 2 M | J13: 200634005227 | L13: YES | N13: 5 | O13: =VLOOKUP(N13,$A$162:$B$172,2,FALSE) -> ASH-SHAIKH HARSAN | P13: =VLOOKUP(N13,$A$162:$C$172,3,FALSE) -> 0774746493 / 0719150788 | R13: SHAREE'AH | S13: KALUTARA | T13: 68/4, MARIKAR STREETS, KALUTHARA SOUTH. | U13: 757510962
A14: 371 | B14: ABDUR RAHMAN JABIR ALI | E14: 371 | F14: J.A.ABDUR RAHMAN | G14: JABIR ALI ABDUR RAHAMN | H14: 38485 | I14: =DATEDIF(H14, TODAY(), "Y") & " Y " & DATEDIF(H14, TODAY(), "YM") & " M" -> 20 Y 8 M | J14: 200513404923 | L14: YES | N14: 5 | O14: =VLOOKUP(N14,$A$162:$B$172,2,FALSE) -> ASH-SHAIKH HARSAN | P14: =VLOOKUP(N14,$A$162:$C$172,3,FALSE) -> 0774746493 / 0719150788 | R14: SHAREE'AH | S14: KALUTARA | T14: 42/28, ALWIS PLACE, KALUTHARA SOUTH. | U14: 758978987
A15: 381 | B15: UMAR SAIFULLAH | E15: 381 | F15: M.S.UMAR | G15: MUHAMMAD SAIFULLAH UMAR | H15: 38629 | I15: =DATEDIF(H15, TODAY(), "Y") & " Y " & DATEDIF(H15, TODAY(), "YM") & " M" -> 20 Y 4 M | J15: 200527805087 | L15: YES | N15: 5 | O15: =VLOOKUP(N15,$A$162:$B$172,2,FALSE) -> ASH-SHAIKH HARSAN | P15: =VLOOKUP(N15,$A$162:$C$172,3,FALSE) -> 0774746493 / 0719150788 | R15: SHAREE'AH | S15: KALUTARA | T15: 103, HANAFI MAWATHA, MARADANA, BERUWELA. | U15: 775205760
A16: 383 | B16: ABDUR RAHMAN ALIYAR | E16: 383 | F16: M.A.ABDUR RAHMAN | G16: MUHAMMAD ALIYAR ABDUR RAHMAN | H16: 38768 | I16: =DATEDIF(H16, TODAY(), "Y") & " Y " & DATEDIF(H16, TODAY(), "YM") & " M" -> 19 Y 11 M | J16: 200605100127 | L16: YES | N16: 6 | O16: =VLOOKUP(N16,$A$162:$B$172,2,FALSE) -> ASH-SHAIKH SHAHEER AHMED | P16: =VLOOKUP(N16,$A$162:$C$172,3,FALSE) -> 757296619 | R16: SHAREE'AH | S16: KALUTARA | T16: 40/11A, LOTES ROAD, DHARGA TOWN. | U16: 770646880
A17: 384 | B17: MUHAMMADH MUSHIR KHAN | E17: 384 | F17: M.M.MUHAMMAD | G17: MUHAMMAD MUSHEER KHAN MUHAMMAD | H17: 38806 | I17: =DATEDIF(H17, TODAY(), "Y") & " Y " & DATEDIF(H17, TODAY(), "YM") & " M" -> 19 Y 10 M | J17: 200626301569 | L17: YES | N17: 5 | O17: =VLOOKUP(N17,$A$162:$B$172,2,FALSE) -> ASH-SHAIKH HARSAN | P17: =VLOOKUP(N17,$A$162:$C$172,3,FALSE) -> 0774746493 / 0719150788 | R17: SHAREE'AH | S17: HAMPANTHOTA | T17: J/19, SRI BO PURA, HAMBANTHOTA. | U17: 754743743
A18: 404 | B18: ASA'DH MUSADIQ | E18: 404 | F18: M.M.M.AS'ADH | G18: MUHAMMAD MUSADHIK MUHAMMAD AS'ADH | H18: 39070 | I18: =DATEDIF(H18, TODAY(), "Y") & " Y " & DATEDIF(H18, TODAY(), "YM") & " M" -> 19 Y 1 M | J18: 200635404723 | L18: YES | N18: 5 | O18: =VLOOKUP(N18,$A$162:$B$172,2,FALSE) -> ASH-SHAIKH HARSAN | P18: =VLOOKUP(N18,$A$162:$C$172,3,FALSE) -> 0774746493 / 0719150788 | R18: SHAREE'AH | S18: KALUTARA | T18: 155/43, MARADANA RD, BERUWALA. | U18: 764001178
A19: 408 | B19: HUSSAIN WASEEM | E19: 408 | F19: M.W.M.HUSAIN | G19: MUHAMMAD WASEEM MUHAMMAD HUSAIN | H19: 39814 | I19: =DATEDIF(H19, TODAY(), "Y") & " Y " & DATEDIF(H19, TODAY(), "YM") & " M" -> 17 Y 1 M | J19: 200900102814 | L19: YES | N19: 4 | O19: =VLOOKUP(N19,$A$162:$B$172,2,FALSE) -> ASH-SHAIKH MUNTHASIR | P19: =VLOOKUP(N19,$A$162:$C$172,3,FALSE) -> 0762663436 / 0755050300 | R19: SHAREE'AH | S19: KALUTARA | T19: 0 | U19: 777434380
A20: 410 | B20: MUHAMMADH ASNAF | E20: 410 | F20: A.H.MUHAMMAD | G20: ASNAF HASAN MUHAMMAD | H20: 37364 | I20: =DATEDIF(H20, TODAY(), "Y") & " Y " & DATEDIF(H20, TODAY(), "YM") & " M" -> 23 Y 9 M | J20: 200210910466 | L20: YES | N20: 5 | O20: =VLOOKUP(N20,$A$162:$B$172,2,FALSE) -> ASH-SHAIKH HARSAN | P20: =VLOOKUP(N20,$A$162:$C$172,3,FALSE) -> 0774746493 / 0719150788 | R20: SHAREE'AH | S20: KALUTARA | T20: 6/3, MORE STREET, KALUTHARA SOUTH. | U20: 0777520145 / 0758528229
A21: 413 | B21: YOOSUF AROOS | E21: 413 | F21: M.A.M.YOOSUF | G21: MUHAMMAD AROOS MUHAMMAD YOOSUF | H21: 38744 | I21: =DATEDIF(H21, TODAY(), "Y") & " Y " & DATEDIF(H21, TODAY(), "YM") & " M" -> 20 Y 0 M | J21: 200602704679 | L21: YES | N21: 4 | O21: =VLOOKUP(N21,$A$162:$B$172,2,FALSE) -> ASH-SHAIKH MUNTHASIR | P21: =VLOOKUP(N21,$A$162:$C$172,3,FALSE) -> 0762663436 / 0755050300 | R21: SHAREE'AH | S21: KALUTARA | T21: 14/B, MUSLIM RD, WELIPPANNA. | U21: 775332539
A22: 420 | B22: FASLULLAH IQBAL | E22: 420 | F22: M.I.M.FASRULLAH | G22: MUHAMMAD IQBAL MUHAMMAD FASRULLAH | H22: 39239 | I22: =DATEDIF(H22, TODAY(), "Y") & " Y " & DATEDIF(H22, TODAY(), "YM") & " M" -> 18 Y 7 M | J22: 200716502128 | L22: YES | N22: 3 | O22: =VLOOKUP(N22,$A$162:$B$172,2,FALSE) -> ASH-SHAIKH IHTHISHAM | P22: =VLOOKUP(N22,$A$162:$C$172,3,FALSE) -> 0770836023 / 0783027491 | R22: SHAREE'AH | S22: KALUTARA | T22: 44/C, MAHA HINATHI YANGALA, KALUTHARA. | U22: 756308746
A23: 426 | B23: YAHYA SINAN | E23: 426 | F23: M.S.M.YAHYA | G23: MUHAMMAD SINAN MUHAMMAD YAHYA | H23: 39491 | I23: =DATEDIF(H23, TODAY(), "Y") & " Y " & DATEDIF(H23, TODAY(), "YM") & " M" -> 17 Y 11 M | J23: 200804400842 | L23: YES | N23: 3 | O23: =VLOOKUP(N23,$A$162:$B$172,2,FALSE) -> ASH-SHAIKH IHTHISHAM | P23: =VLOOKUP(N23,$A$162:$C$172,3,FALSE) -> 0770836023 / 0783027491 | R23: SHAREE'AH | S23: KALUTARA | T23: 56, MOSQUE ROAD, PALANDHA, AGULAWATTHA. | U23: 775513799
A24: 429 | B24: RIKAS RIMZAN | E24: 429 | F24: M.R.M.RIKAS | G24: MUHAMMAD RIMSAN MUHAMMAD RIKAS | H24: 38811 | I24: =DATEDIF(H24, TODAY(), "Y") & " Y " & DATEDIF(H24, TODAY(), "YM") & " M" -> 19 Y 10 M | J24: 200509505560 | L24: NO | M24: Death | N24: 7 | O24: =VLOOKUP(N24,$A$162:$B$172,2,FALSE) -> ASH-SHAIKH FAYZEEN | P24: =VLOOKUP(N24,$A$162:$C$172,3,FALSE) -> 0775020033 / 0761792209 | R24: SHAREE'AH | S24: KALUTARA | T24: 90/5A, GONAYARAMBA, BOGALLA, BERUWELA. | U24: 0725615702 / 0725615722
A25: 430 | B25: MUKRIM ZUHAIR | E25: 430 | F25: M.Z.M.MUKRIM | G25: MUHAMMAD ZUHAIR MUHAMMAD MUKRIM | H25: 39833 | I25: =DATEDIF(H25, TODAY(), "Y") & " Y " & DATEDIF(H25, TODAY(), "YM") & " M" -> 17 Y 0 M | L25: YES | N25: 3 | O25: =VLOOKUP(N25,$A$162:$B$172,2,FALSE) -> ASH-SHAIKH IHTHISHAM | P25: =VLOOKUP(N25,$A$162:$C$172,3,FALSE) -> 0770836023 / 0783027491 | R25: SHAREE'AH | S25: KALUTARA | T25: 423/09, GALLE ROAD, KALUTHARA SOUTH. | U25: 771402747
A26: 431 | B26: ALI FARSHAN | E26: 431 | F26: M.F.MUHAMMAD ALI | G26: MUHAMMAD FARSAN MUHAMMAD ALI | H26: 40119 | I26: =DATEDIF(H26, TODAY(), "Y") & " Y " & DATEDIF(H26, TODAY(), "YM") & " M" -> 16 Y 3 M | J26: 200630701248 | L26: YES | N26: 3 | O26: =VLOOKUP(N26,$A$162:$B$172,2,FALSE) -> ASH-SHAIKH IHTHISHAM | P26: =VLOOKUP(N26,$A$162:$C$172,3,FALSE) -> 0770836023 / 0783027491 | R26: SHAREE'AH | S26: KALUTARA | T26: 26, SRI SHANDARMA WAMSHA MAWATTHA, KALUTHARA SOUTH. | U26: 771638348
A27: 433 | B27: USMAN FAZAL | E27: 433 | F27: M.F.M.USMAN | G27: MUHAMMAD FASAL MUHAMMAD USMAN | H27: 39760 | I27: =DATEDIF(H27, TODAY(), "Y") & " Y " & DATEDIF(H27, TODAY(), "YM") & " M" -> 17 Y 2 M | J27: 200831301360 | L27: YES | N27: 3 | O27: =VLOOKUP(N27,$A$162:$B$172,2,FALSE) -> ASH-SHAIKH IHTHISHAM | P27: =VLOOKUP(N27,$A$162:$C$172,3,FALSE) -> 0770836023 / 0783027491 | R27: SHAREE'AH | S27: KALUTARA | T27: 26/12A, MOOR STREET, KALUTHARA SOUTH. | U27: 774898376
A28: 437 | B28: ABDUR RAHMAN NIZAR | E28: 437 | F28: M.N.ABDUR RAHMAN | G28: MUHAMMAD NISAR ABDUR RAHMAN | H28: 39516 | I28: =DATEDIF(H28, TODAY(), "Y") & " Y " & DATEDIF(H28, TODAY(), "YM") & " M" -> 17 Y 10 M | L28: NO | M28: Death | N28: 3 | O28: =VLOOKUP(N28,$A$162:$B$172,2,FALSE) -> ASH-SHAIKH IHTHISHAM | P28: =VLOOKUP(N28,$A$162:$C$172,3,FALSE) -> 0770836023 / 0783027491 | R28: SHAREE'AH | S28: KALUTARA | T28: 68/3,KEERANTHITIYA RD, BOGALLA, BERUWALA. | U28: 770781870
A29: 441 | B29: ABDUR RAHMAN RAHMATHULLAH | E29: 441 | F29: M.R.ABDUR RAHMAN | G29: MUHAMMAD RAHMATHUULAH ABDUR RAHMAN | H29: 39256 | I29: =DATEDIF(H29, TODAY(), "Y") & " Y " & DATEDIF(H29, TODAY(), "YM") & " M" -> 18 Y 7 M | J29: 200717501681 | L29: YES | N29: 3 | O29: =VLOOKUP(N29,$A$162:$B$172,2,FALSE) -> ASH-SHAIKH IHTHISHAM | P29: =VLOOKUP(N29,$A$162:$C$172,3,FALSE) -> 0770836023 / 0783027491 | R29: SHAREE'AH | S29: KALUTARA | T29: NO:114/2, AL-MINHAJ LANE,WELIPPENA. | U29: 772084496
A30: 443 | B30: YOONUS MUMTHAZ | E30: 443 | F30: M.M.M.YOUNUS | G30: MUHAMMAD MUMTHAZ MUHAMMAD YOUNUS | H30: 39348 | I30: =DATEDIF(H30, TODAY(), "Y") & " Y " & DATEDIF(H30, TODAY(), "YM") & " M" -> 18 Y 4 M | J30: 200726703935 | L30: YES | N30: 3 | O30: =VLOOKUP(N30,$A$162:$B$172,2,FALSE) -> ASH-SHAIKH IHTHISHAM | P30: =VLOOKUP(N30,$A$162:$C$172,3,FALSE) -> 0770836023 / 0783027491 | R30: SHAREE'AH | S30: KALUTARA | T30: NO:121, NOOR MAHAL,THUNDUWA,HABURUGALA. | U30: 775939246
A31: 449 | B31: MUHAMMED YOUSUF RIYAZ | E31: 449 | F31: M.R.M.YOUSUF | G31: MUHAMMAD RIYAS MUHAMMAD YOUSUF | H31: 39472 | I31: =DATEDIF(H31, TODAY(), "Y") & " Y " & DATEDIF(H31, TODAY(), "YM") & " M" -> 18 Y 0 M | J31: 200802504674 | L31: YES | N31: 3 | O31: =VLOOKUP(N31,$A$162:$B$172,2,FALSE) -> ASH-SHAIKH IHTHISHAM | P31: =VLOOKUP(N31,$A$162:$C$172,3,FALSE) -> 0770836023 / 0783027491 | R31: SHAREE'AH | S31: KALUTARA | T31: A/21/2/211,MASJID ROAD,ABBALANDUWA, PANADURA. | U31: 756089311
A32: 451 | B32: ABDULLAH NIZAR | E32: 451 | F32: M.N.ABDULLAH | G32: MUHAMMAD NISAR ABDULLAH | H32: 39302 | I32: =DATEDIF(H32, TODAY(), "Y") & " Y " & DATEDIF(H32, TODAY(), "YM") & " M" -> 18 Y 5 M | J32: 200722105104 | L32: YES | N32: 3 | O32: =VLOOKUP(N32,$A$162:$B$172,2,FALSE) -> ASH-SHAIKH IHTHISHAM | P32: =VLOOKUP(N32,$A$162:$C$172,3,FALSE) -> 0770836023 / 0783027491 | R32: SHAREE'AH | S32: GAMPAHA | T32: 165/18, VEERATHANIYA WATHAA, PASYALA. | U32: 779662465
A33: 452 | B33: ABDULLAH JABIR ALI | E33: 452 | F33: J.A.ABDULLAH | G33: JABIR ALI ABDULLAH | H33: 39583 | I33: =DATEDIF(H33, TODAY(), "Y") & " Y " & DATEDIF(H33, TODAY(), "YM") & " M" -> 17 Y 8 M | J33: 200813603833 | L33: YES | N33: 3 | O33: =VLOOKUP(N33,$A$162:$B$172,2,FALSE) -> ASH-SHAIKH IHTHISHAM | P33: =VLOOKUP(N33,$A$162:$C$172,3,FALSE) -> 0770836023 / 0783027491 | R33: SHAREE'AH | S33: KALUTARA | T33: 42/28, A.D ALWIS PLACE, KALUTHARA SOUTH. | U33: 770454761
A34: 454 | B34: MUHAMED SAJATH HAMZA | E34: 454 | F34: M.H.M.SAJATH | G34: MUHAMMAD HAMZA MUHAMMAD SAJATH | H34: 39496 | I34: =DATEDIF(H34, TODAY(), "Y") & " Y " & DATEDIF(H34, TODAY(), "YM") & " M" -> 17 Y 11 M | L34: YES | N34: 3 | O34: =VLOOKUP(N34,$A$162:$B$172,2,FALSE) -> ASH-SHAIKH IHTHISHAM | P34: =VLOOKUP(N34,$A$162:$C$172,3,FALSE) -> 0770836023 / 0783027491 | R34: SHAREE'AH | S34: KALUTARA | T34: 64,WETHIMA RAJA PURA , MARADANA, BERUWALA. | U34: 756395948
A35: 455 | B35: ISHFAK IRFAN | E35: 455 | F35: M.I.ISHFAQ | G35: MUHAMMAD IRFAN ISHFAQ AHMADH | H35: 38597 | I35: =DATEDIF(H35, TODAY(), "Y") & " Y " & DATEDIF(H35, TODAY(), "YM") & " M" -> 20 Y 5 M | J35: 200524600862 | L35: YES | N35: 5 | O35: =VLOOKUP(N35,$A$162:$B$172,2,FALSE) -> ASH-SHAIKH HARSAN | P35: =VLOOKUP(N35,$A$162:$C$172,3,FALSE) -> 0774746493 / 0719150788 | R35: SHAREE'AH | S35: KALUTARA | T35: 72/3, MUSLIM STREET, TANGALLA. | U35: 771248524
A36: 458 | B36: AHMADH FAIZAL | E36: 458 | F36: M.F.AHMADH | G36: MUHAMMAD FAISAL AHMADH | H36: 38616 | I36: =DATEDIF(H36, TODAY(), "Y") & " Y " & DATEDIF(H36, TODAY(), "YM") & " M" -> 20 Y 4 M | J36: 200526504063 | L36: YES | N36: 5 | O36: =VLOOKUP(N36,$A$162:$B$172,2,FALSE) -> ASH-SHAIKH HARSAN | P36: =VLOOKUP(N36,$A$162:$C$172,3,FALSE) -> 0774746493 / 0719150788 | R36: SHAREE'AH | S36: KALUTARA | T36: 120,JAYA SUNDARA MW, KALUTARA SOUTH | U36: 759904501
A37: 459 | B37: IHLAS IRSHADH | E37: 459 | F37: IHLAS IRSHADH | G37: IRSHADH | H37: 40463 | I37: =DATEDIF(H37, TODAY(), "Y") & " Y " & DATEDIF(H37, TODAY(), "YM") & " M" -> 15 Y 3 M | L37: YES | N37: 1 | O37: =VLOOKUP(N37,$A$162:$B$172,2,FALSE) -> ASH-SHAIKH FAYZEEN | P37: =VLOOKUP(N37,$A$162:$C$172,3,FALSE) -> 0775020033 / 0761792209 | R37: SHAREE'AH | S37: KALUTARA | T37: 107,MARADANA, BERUWALA. | U37: 778535209 | AE37: 755881563 0740685959
A38: 461 | B38: AADHIL AMEEN | E38: 461 | F38: AADHIL AMEEN | G38: AMEEN | H38: 40938 | I38: =DATEDIF(H38, TODAY(), "Y") & " Y " & DATEDIF(H38, TODAY(), "YM") & " M" -> 14 Y 0 M | L38: YES | N38: 1 | O38: =VLOOKUP(N38,$A$162:$B$172,2,FALSE) -> ASH-SHAIKH FAYZEEN | P38: =VLOOKUP(N38,$A$162:$C$172,3,FALSE) -> 0775020033 / 0761792209 | R38: SHAREE'AH | S38: KALUTARA | T38: 26/16H, MOOR STREET, KALUTARA SOUTH. | U38: 752109278
A39: 462 | B39: ARKAM SHIFAN | E39: 462 | F39: ARKAM SHIFAN | G39: SHIFAN | H39: 40565 | I39: =DATEDIF(H39, TODAY(), "Y") & " Y " & DATEDIF(H39, TODAY(), "YM") & " M" -> 15 Y 0 M | L39: YES | N39: 2 | O39: =VLOOKUP(N39,$A$162:$B$172,2,FALSE) -> ASH-SHAIKH ILHAM | P39: =VLOOKUP(N39,$A$162:$C$172,3,FALSE) -> 0775771676 / 0754618392 | R39: SHAREE'AH | S39: KALUTARA | T39: 30/5A, KADIYA WATTA ROAD, DARGA TOWN. | U39: 770456458
A40: 467 | B40: MAHMOODH MUSHIR KHAN | E40: 467 | F40: M.MAHMOODH | G40: MUSHIR KHAN MUSHI KHAN | H40: 40033 | I40: =DATEDIF(H40, TODAY(), "Y") & " Y " & DATEDIF(H40, TODAY(), "YM") & " M" -> 16 Y 5 M | J40: 200922103493 | L40: YES | N40: 2 | O40: =VLOOKUP(N40,$A$162:$B$172,2,FALSE) -> ASH-SHAIKH ILHAM | P40: =VLOOKUP(N40,$A$162:$C$172,3,FALSE) -> 0775771676 / 0754618392 | R40: SHAREE'AH | S40: HAMPANTHOTA | T40: 30/5A, KADIYA WATTA ROAD, DARGA TOWN. | U40: 0717255136 / 0714096631
...

Sheet Sheet1
A1: Admision No | B1: Name with initial | C1: Full Name | D1: Date of Birth | E1: Age | F1: N.I.C Number | G1: Date of Admision | H1: Father 's Status Alive / Deceased | I1: Father | J1: Grade in madrasa | K1: Class Usthadh | L1: Class Usthadh Contact Number | M1: Grade in School | N1: Section | O1: Distric | P1: Address | Q1: Contact
A2: 243 | B2: A.L.M.AKMAL | C2: ABDUL LATHEEF MUHAMMAD AKMAL | D2: 36875 | E2: =DATEDIF(D2, TODAY(), "Y") & " Y " & DATEDIF(D2, TODAY(), "YM") & " M" -> 25 Y 1 M | F2: 200035003262 | H2: YES | J2: 7 | K2: =VLOOKUP(J2,$A$162:$B$179,2,FALSE) -> #N/A | L2: =VLOOKUP(J2,$A$162:$C$179,3,FALSE) -> #N/A | N2: SHAREE'AH | O2: KALUTARA | P2: 15/18A, MADAKISSA RD, HORETHUDUWE, KESALWATTA. | Q2: 0777705940 / 0755764243
A3: 248 | B3: M.I.M.ISHFAQ | C3: MUHAMMAD ILFAN MUHAMMAD ISHFAQ | D3: 37316 | E3: =DATEDIF(D3, TODAY(), "Y") & " Y " & DATEDIF(D3, TODAY(), "YM") & " M" -> 23 Y 11 M | F3: 200206103934 | H3: YES | J3: 7 | K3: =VLOOKUP(J3,$A$162:$B$179,2,FALSE) -> #N/A | L3: =VLOOKUP(J3,$A$162:$C$179,3,FALSE) -> #N/A | N3: SHAREE'AH | O3: KALUTARA | P3: 73/6,TSNAMI HOUSES, DHARGA RD, BERUWELA. | Q3: 0769455844 / 0774008535
A4: 250 | B4: M.A.M.FAISAL | C4: MUHAMMAD ASHRAF MUHAMMAD FAISAL | D4: 37702 | E4: =DATEDIF(D4, TODAY(), "Y") & " Y " & DATEDIF(D4, TODAY(), "YM") & " M" -> 22 Y 10 M | F4: 200308200369 | H4: NO | I4: Death | J4: 7 | K4: =VLOOKUP(J4,$A$162:$B$179,2,FALSE) -> #N/A | L4: =VLOOKUP(J4,$A$162:$C$179,3,FALSE) -> #N/A | N4: SHAREE'AH | O4: KALUTARA | P4: 148/40, KADHIYA WATTA RD, WELIPITIYA, DHARGA TOWN. | Q4: 0770333163 / 0778620559
A5: 325 | B5: M.R.ABDUR RAHMAN | C5: MUHAMMAD RIZWAN ABDUR RAHMAN | D5: 37891 | E5: =DATEDIF(D5, TODAY(), "Y") & " Y " & DATEDIF(D5, TODAY(), "YM") & " M" -> 22 Y 4 M | F5: 200327113163 | H5: YES | J5: 7 | K5: =VLOOKUP(J5,$A$162:$B$179,2,FALSE) -> #N/A | L5: =VLOOKUP(J5,$A$162:$C$179,3,FALSE) -> #N/A | N5: SHAREE'AH | O5: PUTTALAM | P5: HIJRA LANE, PUTHUKUDIERUPPU, BATTULU OYA. | Q5: 0717257977 / 0775856331
A6: 331 | B6: M.I.ABDULLAH | C6: MUHAMMAD IJAZ ABDULLAH | D6: 38586 | E6: =DATEDIF(D6, TODAY(), "Y") & " Y " & DATEDIF(D6, TODAY(), "YM") & " M" -> 20 Y 5 M | F6: 200522901050 | H6: YES | J6: 4 | K6: =VLOOKUP(J6,$A$162:$B$179,2,FALSE) -> #N/A | L6: =VLOOKUP(J6,$A$162:$C$179,3,FALSE) -> #N/A | N6: SHAREE'AH | O6: KALUTARA | P6: 20/7, S,M LANE, WELPITIYA, DARGA TOWN. | Q6: 0
A7: 341 | B7: M.M.AHMAD | C7: MMUHAMMAD MAFAIZ AHMAD | D7: 38528 | E7: =DATEDIF(D7, TODAY(), "Y") & " Y " & DATEDIF(D7, TODAY(), "YM") & " M" -> 20 Y 7 M | F7: 200517704065 | H7: YES | J7: 5 | K7: =VLOOKUP(J7,$A$162:$B$179,2,FALSE) -> #N/A | L7: =VLOOKUP(J7,$A$162:$C$179,3,FALSE) -> #N/A | N7: SHAREE'AH | O7: KALUTARA | P7: 41,THOTAWATHA, PANADURA. | Q7: 772696059
A8: 342 | B8: M.I.M. ILHAM | C8: MUHAMMAD IRFAN MUHAMMAD ILHAM | D8: 38519 | E8: =DATEDIF(D8, TODAY(), "Y") & " Y " & DATEDIF(D8, TODAY(), "YM") & " M" -> 20 Y 7 M | F8: 200516803973 | H8: YES | J8: 6 | K8: =VLOOKUP(J8,$A$162:$B$179,2,FALSE) -> #N/A | L8: =VLOOKUP(J8,$A$162:$C$179,3,FALSE) -> #N/A | N8: SHAREE'AH | O8: KALUTARA | P8: 68/4,MARIKAR STREETS, KALUTHARA SOUTH. | Q8: 757510962
A9: 345 | B9: M.S.M.AHSAN | C9: MUHAMMAD SHAKIR MUHAMMAD AHSAN | D9: 38162 | E9: =DATEDIF(D9, TODAY(), "Y") & " Y " & DATEDIF(D9, TODAY(), "YM") & " M" -> 21 Y 7 M | F9: 200417800580 | H9: YES | J9: 6 | K9: =VLOOKUP(J9,$A$162:$B$179,2,FALSE) -> #N/A | L9: =VLOOKUP(J9,$A$162:$C$179,3,FALSE) -> #N/A | N9: SHAREE'AH | O9: KALUTARA | P9: 387/1, IBRAHEEM HAJIAR MW, A,BAMUNU MULLA , ATULUGAMA , BANDARA GAMA. | Q9: 763433801
A10: 354 | B10: M.M. ABDULLAH | C10: MUHAMMAD MUNDHIR ABDULLAH | D10: 37944 | E10: =DATEDIF(D10, TODAY(), "Y") & " Y " & DATEDIF(D10, TODAY(), "YM") & " M" -> 22 Y 2 M | F10: 200332413390 | H10: YES | J10: 7 | K10: =VLOOKUP(J10,$A$162:$B$179,2,FALSE) -> #N/A | L10: =VLOOKUP(J10,$A$162:$C$179,3,FALSE) -> #N/A | N10: SHAREE'AH | O10: KALUTARA | P10: 16, ZAVIYA RD, MAHAGODA, BERUWELA. | Q10: 0768822240 / 0778119004
A11: 356 | B11: N.M.SHAFRAN | C11: NALEEM MUHAMMAD SAFRAN | D11: 37989 | E11: =DATEDIF(D11, TODAY(), "Y") & " Y " & DATEDIF(D11, TODAY(), "YM") & " M" -> 22 Y 1 M | F11: 200500504225 | H11: YES | J11: 5 | K11: =VLOOKUP(J11,$A$162:$B$179,2,FALSE) -> #N/A | L11: =VLOOKUP(J11,$A$162:$C$179,3,FALSE) -> #N/A | N11: SHAREE'AH | O11: TRINCOMALEE | P11: 104, KINNIYA, ANNA NAGAR. | Q11: 755093414
A12: 363 | B12: M.I.M. IKRAM | C12: MUHAMMAD IRFAN MUHAMMAD IKRAM | D12: 39056 | E12: =DATEDIF(D12, TODAY(), "Y") & " Y " & DATEDIF(D12, TODAY(), "YM") & " M" -> 19 Y 2 M | F12: 200634005227 | H12: YES | J12: 5 | K12: =VLOOKUP(J12,$A$162:$B$179,2,FALSE) -> #N/A | L12: =VLOOKUP(J12,$A$162:$C$179,3,FALSE) -> #N/A | N12: SHAREE'AH | O12: KALUTARA | P12: 68/4, MARIKAR STREETS, KALUTHARA SOUTH. | Q12: 757510962
A13: 371 | B13: J.A.ABDUR RAHMAN | C13: JABIR ALI ABDUR RAHAMN | D13: 38485 | E13: =DATEDIF(D13, TODAY(), "Y") & " Y " & DATEDIF(D13, TODAY(), "YM") & " M" -> 20 Y 8 M | F13: 200513404923 | H13: YES | J13: 5 | K13: =VLOOKUP(J13,$A$162:$B$179,2,FALSE) -> #N/A | L13: =VLOOKUP(J13,$A$162:$C$179,3,FALSE) -> #N/A | N13: SHAREE'AH | O13: KALUTARA | P13: 42/28, ALWIS PLACE, KALUTHARA SOUTH. | Q13: 758978987
A14: 381 | B14: M.S.UMAR | C14: MUHAMMAD SAIFULLAH UMAR | D14: 38629 | E14: =DATEDIF(D14, TODAY(), "Y") & " Y " & DATEDIF(D14, TODAY(), "YM") & " M" -> 20 Y 4 M | F14: 200527805087 | H14: YES | J14: 5 | K14: =VLOOKUP(J14,$A$162:$B$179,2,FALSE) -> #N/A | L14: =VLOOKUP(J14,$A$162:$C$179,3,FALSE) -> #N/A | N14: SHAREE'AH | O14: KALUTARA | P14: 103, HANAFI MAWATHA, MARADANA, BERUWELA. | Q14: 775205760
A15: 383 | B15: M.A.ABDUR RAHMAN | C15: MUHAMMAD ALIYAR ABDUR RAHMAN | D15: 38768 | E15: =DATEDIF(D15, TODAY(), "Y") & " Y " & DATEDIF(D15, TODAY(), "YM") & " M" -> 19 Y 11 M | F15: 200605100127 | H15: YES | J15: 6 | K15: =VLOOKUP(J15,$A$162:$B$179,2,FALSE) -> #N/A | L15: =VLOOKUP(J15,$A$162:$C$179,3,FALSE) -> #N/A | N15: SHAREE'AH | O15: KALUTARA | P15: 40/11A, LOTES ROAD, DHARGA TOWN. | Q15: 770646880
A16: 384 | B16: M.M.MUHAMMAD | C16: MUHAMMAD MUSHEER KHAN MUHAMMAD | D16: 38806 | E16: =DATEDIF(D16, TODAY(), "Y") & " Y " & DATEDIF(D16, TODAY(), "YM") & " M" -> 19 Y 10 M | F16: 200626301569 | H16: YES | J16: 5 | K16: =VLOOKUP(J16,$A$162:$B$179,2,FALSE) -> #N/A | L16: =VLOOKUP(J16,$A$162:$C$179,3,FALSE) -> #N/A | N16: SHAREE'AH | O16: HAMPANTHOTA | P16: J/19, SRI BO PURA, HAMBANTHOTA. | Q16: 754743743
A17: 404 | B17: M.M.M.AS'ADH | C17: MUHAMMAD MUSADHIK MUHAMMAD AS'ADH | D17: 39070 | E17: =DATEDIF(D17, TODAY(), "Y") & " Y " & DATEDIF(D17, TODAY(), "YM") & " M" -> 19 Y 1 M | F17: 200635404723 | H17: YES | J17: 5 | K17: =VLOOKUP(J17,$A$162:$B$179,2,FALSE) -> #N/A | L17: =VLOOKUP(J17,$A$162:$C$179,3,FALSE) -> #N/A | N17: SHAREE'AH | O17: KALUTARA | P17: 155/43, MARADANA RD, BERUWALA. | Q17: 764001178
A18: 408 | B18: M.W.M.HUSAIN | C18: MUHAMMAD WASEEM MUHAMMAD HUSAIN | D18: 39814 | E18: =DATEDIF(D18, TODAY(), "Y") & " Y " & DATEDIF(D18, TODAY(), "YM") & " M" -> 17 Y 1 M | F18: 200900102814 | H18: YES | J18: 4 | K18: =VLOOKUP(J18,$A$162:$B$179,2,FALSE) -> #N/A | L18: =VLOOKUP(J18,$A$162:$C$179,3,FALSE) -> #N/A | N18: SHAREE'AH | O18: KALUTARA | P18: 0 | Q18: 777434380
A19: 410 | B19: A.H.MUHAMMAD | C19: ASNAF HASAN MUHAMMAD | D19: 37364 | E19: =DATEDIF(D19, TODAY(), "Y") & " Y " & DATEDIF(D19, TODAY(), "YM") & " M" -> 23 Y 9 M | F19: 200210910466 | H19: YES | J19: 5 | K19: =VLOOKUP(J19,$A$162:$B$179,2,FALSE) -> #N/A | L19: =VLOOKUP(J19,$A$162:$C$179,3,FALSE) -> #N/A | N19: SHAREE'AH | O19: KALUTARA | P19: 6/3, MORE STREET, KALUTHARA SOUTH. | Q19: 0777520145 / 0758528229
A20: 413 | B20: M.A.M.YOOSUF | C20: MUHAMMAD AROOS MUHAMMAD YOOSUF | D20: 38744 | E20: =DATEDIF(D20, TODAY(), "Y") & " Y " & DATEDIF(D20, TODAY(), "YM") & " M" -> 20 Y 0 M | F20: 200602704679 | H20: YES | J20: 4 | K20: =VLOOKUP(J20,$A$162:$B$179,2,FALSE) -> #N/A | L20: =VLOOKUP(J20,$A$162:$C$179,3,FALSE) -> #N/A | N20: SHAREE'AH | O20: KALUTARA | P20: 14/B, MUSLIM RD, WELIPPANNA. | Q20: 775332539
A21: 420 | B21: M.I.M.FASRULLAH | C21: MUHAMMAD IQBAL MUHAMMAD FASRULLAH | D21: 39239 | E21: =DATEDIF(D21, TODAY(), "Y") & " Y " & DATEDIF(D21, TODAY(), "YM") & " M" -> 18 Y 7 M | F21: 200716502128 | H21: YES | J21: 3 | K21: =VLOOKUP(J21,$A$162:$B$179,2,FALSE) -> #N/A | L21: =VLOOKUP(J21,$A$162:$C$179,3,FALSE) -> #N/A | N21: SHAREE'AH | O21: KALUTARA | P21: 44/C, MAHA HINATHI YANGALA, KALUTHARA. | Q21: 756308746
A22: 426 | B22: M.S.M.YAHYA | C22: MUHAMMAD SINAN MUHAMMAD YAHYA | D22: 39491 | E22: =DATEDIF(D22, TODAY(), "Y") & " Y " & DATEDIF(D22, TODAY(), "YM") & " M" -> 17 Y 11 M | F22: 200804400842 | H22: YES | J22: 3 | K22: =VLOOKUP(J22,$A$162:$B$179,2,FALSE) -> #N/A | L22: =VLOOKUP(J22,$A$162:$C$179,3,FALSE) -> #N/A | N22: SHAREE'AH | O22: KALUTARA | P22: 56, MOSQUE ROAD, PALANDHA, AGULAWATTHA. | Q22: 775513799
A23: 429 | B23: M.R.M.RIKAS | C23: MUHAMMAD RIMSAN MUHAMMAD RIKAS | D23: 38811 | E23: =DATEDIF(D23, TODAY(), "Y") & " Y " & DATEDIF(D23, TODAY(), "YM") & " M" -> 19 Y 10 M | F23: 200509505560 | H23: NO | I23: Death | J23: 7 | K23: =VLOOKUP(J23,$A$162:$B$179,2,FALSE) -> #N/A | L23: =VLOOKUP(J23,$A$162:$C$179,3,FALSE) -> #N/A | N23: SHAREE'AH | O23: KALUTARA | P23: 90/5A, GONAYARAMBA, BOGALLA, BERUWELA. | Q23: 0725615702 / 0725615722
A24: 430 | B24: M.Z.M.MUKRIM | C24: MUHAMMAD ZUHAIR MUHAMMAD MUKRIM | D24: 39833 | E24: =DATEDIF(D24, TODAY(), "Y") & " Y " & DATEDIF(D24, TODAY(), "YM") & " M" -> 17 Y 0 M | H24: YES | J24: 3 | K24: =VLOOKUP(J24,$A$162:$B$179,2,FALSE) -> #N/A | L24: =VLOOKUP(J24,$A$162:$C$179,3,FALSE) -> #N/A | N24: SHAREE'AH | O24: KALUTARA | P24: 423/09, GALLE ROAD, KALUTHARA SOUTH. | Q24: 771402747
A25: 431 | B25: M.F.MUHAMMAD ALI | C25: MUHAMMAD FARSAN MUHAMMAD ALI | D25: 40119 | E25: =DATEDIF(D25, TODAY(), "Y") & " Y " & DATEDIF(D25, TODAY(), "YM") & " M" -> 16 Y 3 M | F25: 200630701248 | H25: YES | J25: 3 | K25: =VLOOKUP(J25,$A$162:$B$179,2,FALSE) -> #N/A | L25: =VLOOKUP(J25,$A$162:$C$179,3,FALSE) -> #N/A | N25: SHAREE'AH | O25: KALUTARA | P25: 26, SRI SHANDARMA WAMSHA MAWATTHA, KALUTHARA SOUTH. | Q25: 771638348
A26: 433 | B26: M.F.M.USMAN | C26: MUHAMMAD FASAL MUHAMMAD USMAN | D26: 39760 | E26: =DATEDIF(D26, TODAY(), "Y") & " Y " & DATEDIF(D26, TODAY(), "YM") & " M" -> 17 Y 2 M | F26: 200831301360 | H26: YES | J26: 3 | K26: =VLOOKUP(J26,$A$162:$B$179,2,FALSE) -> #N/A | L26: =VLOOKUP(J26,$A$162:$C$179,3,FALSE) -> #N/A | N26: SHAREE'AH | O26: KALUTARA | P26: 26/12A, MOOR STREET, KALUTHARA SOUTH. | Q26: 774898376
A27: 437 | B27: M.N.ABDUR RAHMAN | C27: MUHAMMAD NISAR ABDUR RAHMAN | D27: 39516 | E27: =DATEDIF(D27, TODAY(), "Y") & " Y " & DATEDIF(D27, TODAY(), "YM") & " M" -> 17 Y 10 M | H27: NO | I27: Death | J27: 3 | K27: =VLOOKUP(J27,$A$162:$B$179,2,FALSE) -> #N/A | L27: =VLOOKUP(J27,$A$162:$C$179,3,FALSE) -> #N/A | N27: SHAREE'AH | O27: KALUTARA | P27: 68/3,KEERANTHITIYA RD, BOGALLA, BERUWALA. | Q27: 770781870
A28: 441 | B28: M.R.ABDUR RAHMAN | C28: MUHAMMAD RAHMATHUULAH ABDUR RAHMAN | D28: 39256 | E28: =DATEDIF(D28, TODAY(), "Y") & " Y " & DATEDIF(D28, TODAY(), "YM") & " M" -> 18 Y 7 M | F28: 200717501681 | H28: YES | J28: 3 | K28: =VLOOKUP(J28,$A$162:$B$179,2,FALSE) -> #N/A | L28: =VLOOKUP(J28,$A$162:$C$179,3,FALSE) -> #N/A | N28: SHAREE'AH | O28: KALUTARA | P28: NO:114/2, AL-MINHAJ LANE,WELIPPENA. | Q28: 772084496
A29: 443 | B29: M.M.M.YOUNUS | C29: MUHAMMAD MUMTHAZ MUHAMMAD YOUNUS | D29: 39348 | E29: =DATEDIF(D29, TODAY(), "Y") & " Y " & DATEDIF(D29, TODAY(), "YM") & " M" -> 18 Y 4 M | F29: 200726703935 | H29: YES | J29: 3 | K29: =VLOOKUP(J29,$A$162:$B$179,2,FALSE) -> #N/A | L29: =VLOOKUP(J29,$A$162:$C$179,3,FALSE) -> #N/A | N29: SHAREE'AH | O29: KALUTARA | P29: NO:121, NOOR MAHAL,THUNDUWA,HABURUGALA. | Q29: 775939246
A30: 449 | B30: M.R.M.YOUSUF | C30: MUHAMMAD RIYAS MUHAMMAD YOUSUF | D30: 39472 | E30: =DATEDIF(D30, TODAY(), "Y") & " Y " & DATEDIF(D30, TODAY(), "YM") & " M" -> 18 Y 0 M | F30: 200802504674 | H30: YES | J30: 3 | K30: =VLOOKUP(J30,$A$162:$B$179,2,FALSE) -> #N/A | L30: =VLOOKUP(J30,$A$162:$C$179,3,FALSE) -> #N/A | N30: SHAREE'AH | O30: KALUTARA | P30: A/21/2/211,MASJID ROAD,ABBALANDUWA, PANADURA. | Q30: 756089311
A31: 451 | B31: M.N.ABDULLAH | C31: MUHAMMAD NISAR ABDULLAH | D31: 39302 | E31: =DATEDIF(D31, TODAY(), "Y") & " Y " & DATEDIF(D31, TODAY(), "YM") & " M" -> 18 Y 5 M | F31: 200722105104 | H31: YES | J31: 3 | K31: =VLOOKUP(J31,$A$162:$B$179,2,FALSE) -> #N/A | L31: =VLOOKUP(J31,$A$162:$C$179,3,FALSE) -> #N/A | N31: SHAREE'AH | O31: GAMPAHA | P31: 165/18, VEERATHANIYA WATHAA, PASYALA. | Q31: 779662465
A32: 452 | B32: J.A.ABDULLAH | C32: JABIR ALI ABDULLAH | D32: 39583 | E32: =DATEDIF(D32, TODAY(), "Y") & " Y " & DATEDIF(D32, TODAY(), "YM") & " M" -> 17 Y 8 M | F32: 200813603833 | H32: YES | J32: 3 | K32: =VLOOKUP(J32,$A$162:$B$179,2,FALSE) -> #N/A | L32: =VLOOKUP(J32,$A$162:$C$179,3,FALSE) -> #N/A | N32: SHAREE'AH | O32: KALUTARA | P32: 42/28, A.D ALWIS PLACE, KALUTHARA SOUTH. | Q32: 770454761
A33: 454 | B33: M.H.M.SAJATH | C33: MUHAMMAD HAMZA MUHAMMAD SAJATH | D33: 39496 | E33: =DATEDIF(D33, TODAY(), "Y") & " Y " & DATEDIF(D33, TODAY(), "YM") & " M" -> 17 Y 11 M | H33: YES | J33: 3 | K33: =VLOOKUP(J33,$A$162:$B$179,2,FALSE) -> #N/A | L33: =VLOOKUP(J33,$A$162:$C$179,3,FALSE) -> #N/A | N33: SHAREE'AH | O33: KALUTARA | P33: 64,WETHIMA RAJA PURA , MARADANA, BERUWALA. | Q33: 756395948
A34: 455 | B34: M.I.ISHFAQ | C34: MUHAMMAD IRFAN ISHFAQ AHMADH | D34: 38597 | E34: =DATEDIF(D34, TODAY(), "Y") & " Y " & DATEDIF(D34, TODAY(), "YM") & " M" -> 20 Y 5 M | F34: 200524600862 | H34: YES | J34: 5 | K34: =VLOOKUP(J34,$A$162:$B$179,2,FALSE) -> #N/A | L34: =VLOOKUP(J34,$A$162:$C$179,3,FALSE) -> #N/A | N34: SHAREE'AH | O34: KALUTARA | P34: 72/3, MUSLIM STREET, TANGALLA. | Q34: 771248524
A35: 458 | B35: M.F.AHMADH | C35: MUHAMMAD FAISAL AHMADH | D35: 38616 | E35: =DATEDIF(D35, TODAY(), "Y") & " Y " & DATEDIF(D35, TODAY(), "YM") & " M" -> 20 Y 4 M | F35: 200526504063 | H35: YES | J35: 5 | K35: =VLOOKUP(J35,$A$162:$B$179,2,FALSE) -> #N/A | L35: =VLOOKUP(J35,$A$162:$C$179,3,FALSE) -> #N/A | N35: SHAREE'AH | O35: KALUTARA | P35: 120,JAYA SUNDARA MW, KALUTARA SOUTH | Q35: 759904501
A36: 459 | B36: IHLAS IRSHADH | C36: IRSHADH | D36: 40463 | E36: =DATEDIF(D36, TODAY(), "Y") & " Y " & DATEDIF(D36, TODAY(), "YM") & " M" -> 15 Y 3 M | H36: YES | J36: 1 | K36: =VLOOKUP(J36,$A$162:$B$179,2,FALSE) -> #N/A | L36: =VLOOKUP(J36,$A$162:$C$179,3,FALSE) -> #N/A | N36: SHAREE'AH | O36: KALUTARA | P36: 107,MARADANA, BERUWALA. | Q36: 778535209
A37: 461 | B37: AADHIL AMEEN | C37: AMEEN | D37: 40938 | E37: =DATEDIF(D37, TODAY(), "Y") & " Y " & DATEDIF(D37, TODAY(), "YM") & " M" -> 14 Y 0 M | H37: YES | J37: 1 | K37: =VLOOKUP(J37,$A$162:$B$179,2,FALSE) -> #N/A | L37: =VLOOKUP(J37,$A$162:$C$179,3,FALSE) -> #N/A | N37: SHAREE'AH | O37: KALUTARA | P37: 26/16H, MOOR STREET, KALUTARA SOUTH. | Q37: 752109278
A38: 462 | B38: ARKAM SHIFAN | C38: SHIFAN | D38: 40565 | E38: =DATEDIF(D38, TODAY(), "Y") & " Y " & DATEDIF(D38, TODAY(), "YM") & " M" -> 15 Y 0 M | H38: YES | J38: 2 | K38: =VLOOKUP(J38,$A$162:$B$179,2,FALSE) -> #N/A | L38: =VLOOKUP(J38,$A$162:$C$179,3,FALSE) -> #N/A | N38: SHAREE'AH | O38: KALUTARA | P38: 30/5A, KADIYA WATTA ROAD, DARGA TOWN. | Q38: 770456458
A39: 467 | B39: M.MAHMOODH | C39: MUSHIR KHAN MUSHI KHAN | D39: 40033 | E39: =DATEDIF(D39, TODAY(), "Y") & " Y " & DATEDIF(D39, TODAY(), "YM") & " M" -> 16 Y 5 M | F39: 200922103493 | H39: YES | J39: 2 | K39: =VLOOKUP(J39,$A$162:$B$179,2,FALSE) -> #N/A | L39: =VLOOKUP(J39,$A$162:$C$179,3,FALSE) -> #N/A | N39: SHAREE'AH | O39: HAMPANTHOTA | P39: 30/5A, KADIYA WATTA ROAD, DARGA TOWN. | Q39: 0717255136 / 0714096631
A40: 468 | B40: NAFLAN HASSAN | C40: HASSAN | D40: 39931 | E40: =DATEDIF(D40, TODAY(), "Y") & " Y " & DATEDIF(D40, TODAY(), "YM") & " M" -> 16 Y 9 M | H40: YES | J40: 1 | K40: =VLOOKUP(J40,$A$162:$B$179,2,FALSE) -> #N/A | L40: =VLOOKUP(J40,$A$162:$C$179,3,FALSE) -> #N/A | N40: SHAREE'AH | O40: KALUTARA | P40: 12/1, KETHARAMA ROAD, KALUTARA SOUTH. | Q40: 771352534
...

Sheet CHECKING
C3: Student Details 2026
C4: Admision No: | D4: 500
C5: Name with initial | D5: =VLOOKUP($D$4,'2026'!$E$3:$AH$674,2,FALSE) -> M.S.MAHMOODH
C6: Full Name | D6: =VLOOKUP($D$4,'2026'!$E$3:$AH$674,3,FALSE) -> MUHAMMAD SABRY MAHMOODH
C7: Date of Birth | D7: =VLOOKUP($D$4,'2026'!$E$3:$AH$674,4,FALSE) -> 39849
C8: Age | D8: =VLOOKUP($D$4,'2026'!$E$3:$AH$674,5,FALSE) -> 17 Y 0 M
C9: N.I.C Number | D9: =VLOOKUP($D$4,'2026'!$E$3:$AH$674,6,FALSE) -> 200903602467
C10: Date of Admision | D10: =VLOOKUP($D$4,'2026'!$E$3:$AH$674,7,FALSE) -> 04.01.2023
C11: Father | D11: =VLOOKUP($D$4,'2026'!$E$3:$AH$674,9,FALSE) -> 0
C12: Grade( in madrasa) | D12: =VLOOKUP($D$4,'2026'!$E$3:$AH$674,10,FALSE) -> 4
C13: Class Usthadh | D13: =VLOOKUP($D$4,'2026'!$E$3:$AH$674,11,FALSE) -> ASH-SHAIKH MUNTHASIR
C14: Usthadh Contact Number | D14: =VLOOKUP($D$4,'2026'!$E$3:$AH$674,12,FALSE) -> 0762663436 / 0755050300
C15: Grade (in School Subjects) | D15: =VLOOKUP($D$4,'2026'!$E$3:$AH$674,13,FALSE) -> 0
C16: Section | D16: =VLOOKUP($D$4,'2026'!$E$3:$AH$674,14,FALSE) -> SHAREE'AH
C17: Distric | D17: =VLOOKUP($D$4,'2026'!$E$3:$AH$674,15,FALSE) -> KALUTARA
C18: Address | D18: =VLOOKUP($D$4,'2026'!$E$3:$AH$674,16,FALSE) -> 181, HILL STREET, KALUTARA SOUTH.
C19: Contact Number | D19: =VLOOKUP($D$4,'2026'!$E$3:$AH$674,17,FALSE) -> 763746327
D20: =VLOOKUP($D$4,'2026'!$E$3:$AH$674,18,FALSE) -> 0
D21: =VLOOKUP($D$4,'2026'!$E$3:$AH$674,19,FALSE) -> 0
D22: =VLOOKUP($D$4,'2026'!$E$3:$AH$674,20,FALSE) -> 0
D23: =VLOOKUP($D$4,'2026'!$E$3:$AH$674,21,FALSE) -> 0
D24: =VLOOKUP($D$4,'2026'!$E$3:$AH$674,22,FALSE) -> 0
