Workbook

Sheet Sun,Tue,Wed
A1: my; - ]yh`; muGf; fy;Y}up - NgUtis | S1: QhapW
A2: ehshe;j ghlNeu ml;ltid - 2026
A3: 8k; ghlk; | C3: 7k; ghlk; | E3: 6k; ghlk; | G3: ifYUyh J}f;fk;> Y`u; njhOif kw;Wk; gfYzT Neuk; 01:45 - 11:30 | H3: 5k; ghlk; | J3: 4k; ghlk; | L3: ,ilNtis 10:10 - 9:55 | M3: 3k; ghlk; | O3: 2k; ghlk; | Q3: 1k; ghlk; | S3: ghl myF | T3: 8 | U3: 7 | V3: 6 | W3: 5 | X3: 4 | Y3: 3 | Z3: 2 | AA3: 1 | AB3: ghl myF
A4: 3:05 -3:45 | C4: 2:25 - 3:05 | E4: 1:45 - 2:25 | H4: 10:50 - 11:30 | J4: 10:10 - 10:50 | M4: 9:05 - 9:55 | O4: 8:25 - 9:05 | Q4: 7:35 - 8:25
A5: =VLOOKUP(T5,'Name List'!$C$2:$F$98,4,FALSE) -> 26 | B5: =VLOOKUP(T5,'Name List'!$C$2:$F$98,2,FALSE) -> ]u;g; (2) | C5: =VLOOKUP(U5,'Name List'!$C$2:$F$98,4,FALSE) -> 28 | D5: =VLOOKUP(U5,'Name List'!$C$2:$F$98,2,FALSE) -> muG vOj;jzp | E5: =VLOOKUP(V5,'Name List'!$C$2:$F$98,4,FALSE) -> 36 | F5: =VLOOKUP(V5,'Name List'!$C$2:$F$98,2,FALSE) -> j[;tPj; | H5: =VLOOKUP(W5,'Name List'!$C$2:$F$98,4,FALSE) -> 39 | I5: =VLOOKUP(W5,'Name List'!$C$2:$F$98,2,FALSE) -> ,yf;fzk; | J5: =VLOOKUP(X5,'Name List'!$C$2:$F$98,4,FALSE) -> 44 | K5: =VLOOKUP(X5,'Name List'!$C$2:$F$98,2,FALSE) -> gpf;`; | M5: =VLOOKUP(Y5,'Name List'!$C$2:$F$98,4,FALSE) -> 31 | N5: =VLOOKUP(Y5,'Name List'!$C$2:$F$98,2,FALSE) -> muGg; ghi\ (,d;\h) | O5: =VLOOKUP(Z5,'Name List'!$C$2:$F$98,4,FALSE) -> 41 | P5: =VLOOKUP(Z5,'Name List'!$C$2:$F$98,2,FALSE) -> muGg; ghi\( fpuhj;) | Q5: =VLOOKUP(AA5,'Name List'!$C$2:$F$98,4,FALSE) -> 26 | R5: =VLOOKUP(AA5,'Name List'!$C$2:$F$98,2,FALSE) -> ]u;g; (1) | S5: 1k; tFg;G | T5: 94 | U5: 89 | V5: 84 | W5: 96 | X5: 26 | Y5: 63 | Z5: 64 | AA5: 61 | AB5: 1k; tFg;G
A6: =VLOOKUP(T6,'Name List'!$C$2:$F$98,4,FALSE) -> 31 | B6: =VLOOKUP(T6,'Name List'!$C$2:$F$98,2,FALSE) -> gpf;`; | C6: =VLOOKUP(U6,'Name List'!$C$2:$F$98,4,FALSE) -> 41 | D6: =VLOOKUP(U6,'Name List'!$C$2:$F$98,2,FALSE) -> ,yf;fzk; | E6: =VLOOKUP(V6,'Name List'!$C$2:$F$98,4,FALSE) -> 46 | F6: =VLOOKUP(V6,'Name List'!$C$2:$F$98,2,FALSE) -> muGg; ghi\ (,d;\h) | H6: =VLOOKUP(W6,'Name List'!$C$2:$F$98,4,FALSE) -> 44 | I6: =VLOOKUP(W6,'Name List'!$C$2:$F$98,2,FALSE) -> j[;tPj; | J6: =VLOOKUP(X6,'Name List'!$C$2:$F$98,4,FALSE) -> 28 | K6: =VLOOKUP(X6,'Name List'!$C$2:$F$98,2,FALSE) -> my;Fu;Md; kddk; | M6: =VLOOKUP(Y6,'Name List'!$C$2:$F$98,4,FALSE) -> 44 | N6: =VLOOKUP(Y6,'Name List'!$C$2:$F$98,2,FALSE) -> `jP]; | O6: =VLOOKUP(Z6,'Name List'!$C$2:$F$98,4,FALSE) -> 28 | P6: =VLOOKUP(Z6,'Name List'!$C$2:$F$98,2,FALSE) -> ]u;g; | Q6: =VLOOKUP(AA6,'Name List'!$C$5:$F$99,4,FALSE) -> 44 | R6: =VLOOKUP(AA6,'Name List'!$C$2:$F$98,2,FALSE) -> muGg; ghi\( fpuhj;) | S6: 2k; tFg;G | T6: 27 | U6: 55 | V6: 65 | W6: 85 | X6: 2 | Y6: 16 | Z6: 62 | AA6: 66 | AB6: 2k; tFg;G
A7: =VLOOKUP(T7,'Name List'!$C$2:$F$98,4,FALSE) -> 39 | B7: =VLOOKUP(T7,'Name List'!$C$2:$F$98,2,FALSE) -> j[;tPj; | C7: =VLOOKUP(U7,'Name List'!$C$2:$F$98,4,FALSE) -> 38 | D7: =VLOOKUP(U7,'Name List'!$C$2:$F$98,2,FALSE) -> `jP]; | E7: =VLOOKUP(V7,'Name List'!$C$2:$F$98,4,FALSE) -> 41 | F7: =VLOOKUP(V7,'Name List'!$C$2:$F$98,2,FALSE) -> my;Fu;Md; kddk; | H7: =VLOOKUP(W7,'Name List'!$C$2:$F$98,4,FALSE) -> 28 | I7: =VLOOKUP(W7,'Name List'!$C$2:$F$98,2,FALSE) -> mfPjh | J7: =VLOOKUP(X7,'Name List'!$C$2:$F$98,4,FALSE) -> 41 | K7: =VLOOKUP(X7,'Name List'!$C$2:$F$98,2,FALSE) -> cUJg; ghi\ | M7: =VLOOKUP(Y7,'Name List'!$C$2:$F$98,4,FALSE) -> 38 | N7: =VLOOKUP(Y7,'Name List'!$C$2:$F$98,2,FALSE) -> muGg; ghi\ (,d;\h) | O7: =VLOOKUP(Z7,'Name List'!$C$2:$F$98,4,FALSE) -> 26 | P7: =VLOOKUP(Z7,'Name List'!$C$2:$F$98,2,FALSE) -> gpf;`; | Q7: =VLOOKUP(AA7,'Name List'!$C$8:$F$102,4,FALSE) -> 41 | R7: =VLOOKUP(AA7,'Name List'!$C$2:$F$98,2,FALSE) -> ,yf;fzk; | S7: 3k; tFg;G | T7: 86 | U7: 17 | V7: 3 | W7: 36 | X7: 87 | Y7: 68 | Z7: 28 | AA7: 56 | AB7: 3k; tFg;G
A8: =VLOOKUP(T8,'Name List'!$C$2:$F$98,4,FALSE) -> 46 | B8: =VLOOKUP(T8,'Name List'!$C$2:$F$98,2,FALSE) -> cUJg; ghi\ | C8: =VLOOKUP(U8,'Name List'!$C$2:$F$98,4,FALSE) -> 36 | D8: =VLOOKUP(U8,'Name List'!$C$2:$F$98,2,FALSE) -> tuyhW | E8: =VLOOKUP(V8,'Name List'!$C$2:$F$98,4,FALSE) -> 38 | F8: =VLOOKUP(V8,'Name List'!$C$2:$F$98,2,FALSE) -> mfPjh | H8: =VLOOKUP(W8,'Name List'!$C$2:$F$98,4,FALSE) -> 31 | I8: =VLOOKUP(W8,'Name List'!$C$2:$F$98,2,FALSE) -> gpf;`; | J8: =VLOOKUP(X8,'Name List'!$C$2:$F$98,4,FALSE) -> 46 | K8: =VLOOKUP(X8,'Name List'!$C$2:$F$98,2,FALSE) -> ,yf;fzk; | M8: =VLOOKUP(Y8,'Name List'!$C$2:$F$98,4,FALSE) -> 46 | N8: =VLOOKUP(Y8,'Name List'!$C$2:$F$98,2,FALSE) -> muGg; ghi\ (,d;\h) | O8: =VLOOKUP(Z8,'Name List'!$C$2:$F$98,4,FALSE) -> 39 | P8: =VLOOKUP(Z8,'Name List'!$C$2:$F$98,2,FALSE) -> jg;]Pu; | Q8: =VLOOKUP(AA8,'Name List'!$C$11:$F$105,4,FALSE) -> 46 | R8: =VLOOKUP(AA8,'Name List'!$C$2:$F$98,2,FALSE) -> `jP]; | S8: 4k; tFg;G | T8: 88 | U8: 45 | V8: 37 | W8: 29 | X8: 57 | Y8: 69 | Z8: 8 | AA8: 18 | AB8: 4k; tFg;G
A9: =VLOOKUP(T9,'Name List'!$C$2:$F$98,4,FALSE) -> 36 | B9: =VLOOKUP(T9,'Name List'!$C$2:$F$98,2,FALSE) -> tuyhW | C9: =VLOOKUP(U9,'Name List'!$C$2:$F$98,4,FALSE) -> 36 | D9: =VLOOKUP(U9,'Name List'!$C$2:$F$98,2,FALSE) -> m`;yhf; | E9: =VLOOKUP(V9,'Name List'!$C$2:$F$98,4,FALSE) -> 28 | F9: =VLOOKUP(V9,'Name List'!$C$2:$F$98,2,FALSE) -> gpf;`; | H9: =VLOOKUP(W9,'Name List'!$C$2:$F$98,4,FALSE) -> 46 | I9: =VLOOKUP(W9,'Name List'!$C$2:$F$98,2,FALSE) -> my;Fu;Md; kddk; | J9: =VLOOKUP(X9,'Name List'!$C$2:$F$98,4,FALSE) -> 39 | K9: =VLOOKUP(X9,'Name List'!$C$2:$F$98,2,FALSE) -> muGg; ghi\ (,d;\h) | M9: =VLOOKUP(Y9,'Name List'!$C$2:$F$98,4,FALSE) -> 26 | N9: =VLOOKUP(Y9,'Name List'!$C$2:$F$98,2,FALSE) -> ,yf;fzk; | O9: =VLOOKUP(Z9,'Name List'!$C$2:$F$98,4,FALSE) -> 36 | P9: =VLOOKUP(Z9,'Name List'!$C$2:$F$98,2,FALSE) -> `jP]; | Q9: =VLOOKUP(AA9,'Name List'!$C$15:$F$108,4,FALSE) -> 28 | R9: =VLOOKUP(AA9,'Name List'!$C$2:$F$98,2,FALSE) -> jg;]Pu; | S9: 5k; tFg;G | T9: 46 | U9: 52 | V9: 30 | W9: 5 | X9: 70 | Y9: 58 | Z9: 19 | AA9: 9 | AB9: 5k; tFg;G
A10: =VLOOKUP(T10,'Name List'!$C$2:$F$98,4,FALSE) -> 41 | B10: =VLOOKUP(T10,'Name List'!$C$2:$F$98,2,FALSE) -> `jP]; | C10: =VLOOKUP(U10,'Name List'!$C$2:$F$98,4,FALSE) -> 46 | D10: =VLOOKUP(U10,'Name List'!$C$2:$F$98,2,FALSE) -> mj;ahd; | E10: =VLOOKUP(V10,'Name List'!$C$2:$F$98,4,FALSE) -> 26 | F10: =VLOOKUP(V10,'Name List'!$C$2:$F$98,2,FALSE) -> ,yf;fzk; | H10: =VLOOKUP(W10,'Name List'!$C$2:$F$98,4,FALSE) -> 36 | I10: =VLOOKUP(W10,'Name List'!$C$2:$F$98,2,FALSE) -> tuyhW | J10: =VLOOKUP(X10,'Name List'!$C$2:$F$98,4,FALSE) -> 26 | K10: =VLOOKUP(X10,'Name List'!$C$2:$F$98,2,FALSE) -> gpf;`; | M10: =VLOOKUP(Y10,'Name List'!$C$2:$F$98,4,FALSE) -> 36 | N10: =VLOOKUP(Y10,'Name List'!$C$2:$F$98,2,FALSE) -> jg;]Pu; | O10: =VLOOKUP(Z10,'Name List'!$C$2:$F$98,4,FALSE) -> 31 | P10: =VLOOKUP(Z10,'Name List'!$C$2:$F$98,2,FALSE) -> mfPjh | Q10: =VLOOKUP(AA10,'Name List'!$C$18:$F$111,4,FALSE) -> 39 | R10: =VLOOKUP(AA10,'Name List'!$C$2:$F$98,2,FALSE) -> muGg; ghi\ (,d;\h) | S10: 6k; tFg;G | T10: 20 | U10: 81 | V10: 59 | W10: 47 | X10: 31 | Y10: 10 | Z10: 39 | AA10: 71 | AB10: 6k; tFg;G
A11: =VLOOKUP(T11,'Name List'!$C$2:$F$98,4,FALSE) -> 28 | B11: =VLOOKUP(T11,'Name List'!$C$2:$F$98,2,FALSE) -> jg;]Pu; | C11: =VLOOKUP(U11,'Name List'!$C$2:$F$98,4,FALSE) -> 38 | D11: =VLOOKUP(U11,'Name List'!$C$2:$F$98,2,FALSE) -> kPfhj; | E11: =VLOOKUP(V11,'Name List'!$C$2:$F$98,4,FALSE) -> 31 | F11: =VLOOKUP(V11,'Name List'!$C$2:$F$98,2,FALSE) -> gpuf; | H11: =VLOOKUP(W11,'Name List'!$C$2:$F$98,4,FALSE) -> 26 | I11: =VLOOKUP(W11,'Name List'!$C$2:$F$98,2,FALSE) -> ,yf;fzk; | J11: =VLOOKUP(X11,'Name List'!$C$2:$F$98,4,FALSE) -> 28 | K11: =VLOOKUP(X11,'Name List'!$C$2:$F$98,2,FALSE) -> muGg; ghi\ (,d;\h) | M11: =VLOOKUP(Y11,'Name List'!$C$2:$F$98,4,FALSE) -> 41 | N11: =VLOOKUP(Y11,'Name List'!$C$2:$F$98,2,FALSE) -> `jP]; | O11: =VLOOKUP(Z11,'Name List'!$C$2:$F$98,4,FALSE) -> 41 | P11: =VLOOKUP(Z11,'Name List'!$C$2:$F$98,2,FALSE) -> tuyhW | Q11: =VLOOKUP(AA11,'Name List'!$C$18:$F$111,4,FALSE) -> 31 | R11: =VLOOKUP(AA11,'Name List'!$C$2:$F$98,2,FALSE) -> gpf;`; | S11: 7k; tFg;G | T11: 11 | U11: 82 | V11: 83 | W11: 60 | X11: 72 | Y11: 21 | Z11: 48 | AA11: 32 | AB11: 7k; tFg;G
A12: my; - ]yh`; muGf; fy;Y}up - NgUtis | S12: nrt;tha;
A13: =A2 -> ehshe;j ghlNeu ml;ltid - 2026
A14: 8k; ghlk; | C14: 7k; ghlk; | E14: 6k; ghlk; | G14: ifYUyh J}f;fk;> Y`u; njhOif kw;Wk; gfYzT Neuk; 01:45 - 11:30 | H14: 5k; ghlk; | J14: 4k; ghlk; | L14: ,ilNtis 10:10 - 9:55 | M14: 3k; ghlk; | O14: 2k; ghlk; | Q14: 1k; ghlk; | S14: ghl myF | T14: 8 | U14: 7 | V14: 6 | W14: 5 | X14: 4 | Y14: 3 | Z14: 2 | AA14: 1 | AB14: ghl myF
A15: 3:05 -3:45 | C15: 2:25 - 3:05 | E15: 1:45 - 2:25 | H15: 10:50 - 11:30 | J15: 10:10 - 10:50 | M15: 9:05 - 9:55 | O15: 8:25 - 9:05 | Q15: 7:35 - 8:25
A16: =VLOOKUP(T16,'Name List'!$C$2:$F$98,4,FALSE) -> 26 | B16: =VLOOKUP(T16,'Name List'!$C$2:$F$98,2,FALSE) -> ]u;g; (2) | C16: =VLOOKUP(U16,'Name List'!$C$2:$F$98,4,FALSE) -> 28 | D16: =VLOOKUP(U16,'Name List'!$C$2:$F$98,2,FALSE) -> muG vOj;jzp | E16: =VLOOKUP(V16,'Name List'!$C$2:$F$98,4,FALSE) -> 36 | F16: =VLOOKUP(V16,'Name List'!$C$2:$F$98,2,FALSE) -> fypkhJy; Fu;Md; | H16: =VLOOKUP(W16,'Name List'!$C$2:$F$98,4,FALSE) -> 36 | I16: =VLOOKUP(W16,'Name List'!$C$2:$F$98,2,FALSE) -> my;Fu;Md; kddk; | J16: =VLOOKUP(X16,'Name List'!$C$2:$F$98,4,FALSE) -> 44 | K16: =VLOOKUP(X16,'Name List'!$C$2:$F$98,2,FALSE) -> gpf;`; | M16: =VLOOKUP(Y16,'Name List'!$C$2:$F$98,4,FALSE) -> 31 | N16: =VLOOKUP(Y16,'Name List'!$C$2:$F$98,2,FALSE) -> muGg; ghi\ (,d;\h) | O16: =VLOOKUP(Z16,'Name List'!$C$2:$F$98,4,FALSE) -> 41 | P16: =VLOOKUP(Z16,'Name List'!$C$2:$F$98,2,FALSE) -> muGg; ghi\( fpuhj;) | Q16: =VLOOKUP(AA16,'Name List'!$C$2:$F$98,4,FALSE) -> 26 | R16: =VLOOKUP(AA16,'Name List'!$C$2:$F$98,2,FALSE) -> ]u;g; (1) | S16: 1k; tFg;G | T16: 94 | U16: 89 | V16: 97 | W16: 1 | X16: 26 | Y16: 63 | Z16: 64 | AA16: 61 | AB16: 1k; tFg;G
A17: =VLOOKUP(T17,'Name List'!$C$2:$F$98,4,FALSE) -> 31 | B17: =VLOOKUP(T17,'Name List'!$C$2:$F$98,2,FALSE) -> gpf;`; | C17: =VLOOKUP(U17,'Name List'!$C$2:$F$98,4,FALSE) -> 41 | D17: =VLOOKUP(U17,'Name List'!$C$2:$F$98,2,FALSE) -> ,yf;fzk; | E17: =VLOOKUP(V17,'Name List'!$C$2:$F$98,4,FALSE) -> 46 | F17: =VLOOKUP(V17,'Name List'!$C$2:$F$98,2,FALSE) -> muGg; ghi\ (,d;\h) | H17: =VLOOKUP(W17,'Name List'!$C$2:$F$98,4,FALSE) -> 44 | I17: =VLOOKUP(W17,'Name List'!$C$2:$F$98,2,FALSE) -> tuyhW | J17: =VLOOKUP(X17,'Name List'!$C$2:$F$98,4,FALSE) -> 28 | K17: =VLOOKUP(X17,'Name List'!$C$2:$F$98,2,FALSE) -> muG vOj;jzp | M17: =VLOOKUP(Y17,'Name List'!$C$2:$F$98,4,FALSE) -> 44 | N17: =VLOOKUP(Y17,'Name List'!$C$2:$F$98,2,FALSE) -> `jP]; | O17: =VLOOKUP(Z17,'Name List'!$C$2:$F$98,4,FALSE) -> 28 | P17: =VLOOKUP(Z17,'Name List'!$C$2:$F$98,2,FALSE) -> ]u;g; | Q17: =VLOOKUP(AA17,'Name List'!$C$5:$F$99,4,FALSE) -> 44 | R17: =VLOOKUP(AA17,'Name List'!$C$2:$F$98,2,FALSE) -> muGg; ghi\( fpuhj;) | S17: 2k; tFg;G | T17: 27 | U17: 55 | V17: 65 | W17: 43 | X17: 90 | Y17: 16 | Z17: 62 | AA17: 66 | AB17: 2k; tFg;G
A18: =VLOOKUP(T18,'Name List'!$C$2:$F$98,4,FALSE) -> 36 | B18: =VLOOKUP(T18,'Name List'!$C$2:$F$98,2,FALSE) -> m`;yhf; | C18: =VLOOKUP(U18,'Name List'!$C$2:$F$98,4,FALSE) -> 38 | D18: =VLOOKUP(U18,'Name List'!$C$2:$F$98,2,FALSE) -> `jP]; | E18: =VLOOKUP(V18,'Name List'!$C$2:$F$98,4,FALSE) -> 41 | F18: =VLOOKUP(V18,'Name List'!$C$2:$F$98,2,FALSE) -> ju;[{kJy; Fu;Md; | H18: =VLOOKUP(W18,'Name List'!$C$2:$F$98,4,FALSE) -> 28 | I18: =VLOOKUP(W18,'Name List'!$C$2:$F$98,2,FALSE) -> mfPjh | J18: =VLOOKUP(X18,'Name List'!$C$2:$F$98,4,FALSE) -> 41 | K18: =VLOOKUP(X18,'Name List'!$C$2:$F$98,2,FALSE) -> cUJg; ghi\ | M18: =VLOOKUP(Y18,'Name List'!$C$2:$F$98,4,FALSE) -> 38 | N18: =VLOOKUP(Y18,'Name List'!$C$2:$F$98,2,FALSE) -> muGg; ghi\ (,d;\h) | O18: =VLOOKUP(Z18,'Name List'!$C$2:$F$98,4,FALSE) -> 26 | P18: =VLOOKUP(Z18,'Name List'!$C$2:$F$98,2,FALSE) -> gpf;`; | Q18: =VLOOKUP(AA18,'Name List'!$C$8:$F$102,4,FALSE) -> 41 | R18: =VLOOKUP(AA18,'Name List'!$C$2:$F$98,2,FALSE) -> ,yf;fzk; | S18: 3k; tFg;G | T18: 50 | U18: 17 | V18: 91 | W18: 36 | X18: 87 | Y18: 68 | Z18: 28 | AA18: 56 | AB18: 3k; tFg;G
A19: =VLOOKUP(T19,'Name List'!$C$2:$F$98,4,FALSE) -> 46 | B19: =VLOOKUP(T19,'Name List'!$C$2:$F$98,2,FALSE) -> cUJg; ghi\ | C19: =VLOOKUP(U19,'Name List'!$C$2:$F$98,4,FALSE) -> 39 | D19: =VLOOKUP(U19,'Name List'!$C$2:$F$98,2,FALSE) -> m`;yhf; | E19: =VLOOKUP(V19,'Name List'!$C$2:$F$98,4,FALSE) -> 38 | F19: =VLOOKUP(V19,'Name List'!$C$2:$F$98,2,FALSE) -> mfPjh | H19: =VLOOKUP(W19,'Name List'!$C$2:$F$98,4,FALSE) -> 31 | I19: =VLOOKUP(W19,'Name List'!$C$2:$F$98,2,FALSE) -> gpf;`; | J19: =VLOOKUP(X19,'Name List'!$C$2:$F$98,4,FALSE) -> 46 | K19: =VLOOKUP(X19,'Name List'!$C$2:$F$98,2,FALSE) -> ,yf;fzk; | M19: =VLOOKUP(Y19,'Name List'!$C$2:$F$98,4,FALSE) -> 46 | N19: =VLOOKUP(Y19,'Name List'!$C$2:$F$98,2,FALSE) -> muGg; ghi\ (,d;\h) | O19: =VLOOKUP(Z19,'Name List'!$C$2:$F$98,4,FALSE) -> 39 | P19: =VLOOKUP(Z19,'Name List'!$C$2:$F$98,2,FALSE) -> jg;]Pu; | Q19: =VLOOKUP(AA19,'Name List'!$C$11:$F$105,4,FALSE) -> 46 | R19: =VLOOKUP(AA19,'Name List'!$C$2:$F$98,2,FALSE) -> `jP]; | S19: 4k; tFg;G | T19: 88 | U19: 51 | V19: 37 | W19: 29 | X19: 57 | Y19: 69 | Z19: 8 | AA19: 18 | AB19: 4k; tFg;G
A20: =VLOOKUP(T20,'Name List'!$C$2:$F$98,4,FALSE) -> 39 | B20: =VLOOKUP(T20,'Name List'!$C$2:$F$98,2,FALSE) -> muGg; ghi\ (,d;\h) | C20: =VLOOKUP(U20,'Name List'!$C$2:$F$98,4,FALSE) -> 36 | D20: =VLOOKUP(U20,'Name List'!$C$2:$F$98,2,FALSE) -> m`;yhf; | E20: =VLOOKUP(V20,'Name List'!$C$2:$F$98,4,FALSE) -> 28 | F20: =VLOOKUP(V20,'Name List'!$C$2:$F$98,2,FALSE) -> gpf;`; | H20: =VLOOKUP(W20,'Name List'!$C$2:$F$98,4,FALSE) -> 38 | I20: =VLOOKUP(W20,'Name List'!$C$2:$F$98,2,FALSE) -> ghfg; gpuptpid | J20: =VLOOKUP(X20,'Name List'!$C$2:$F$98,4,FALSE) -> 39 | K20: =VLOOKUP(X20,'Name List'!$C$2:$F$98,2,FALSE) -> muGg; ghi\ (,d;\h) | M20: =VLOOKUP(Y20,'Name List'!$C$2:$F$98,4,FALSE) -> 26 | N20: =VLOOKUP(Y20,'Name List'!$C$2:$F$98,2,FALSE) -> ,yf;fzk; | O20: =VLOOKUP(Z20,'Name List'!$C$2:$F$98,4,FALSE) -> 36 | P20: =VLOOKUP(Z20,'Name List'!$C$2:$F$98,2,FALSE) -> `jP]; | Q20: =VLOOKUP(AA20,'Name List'!$C$15:$F$108,4,FALSE) -> 28 | R20: =VLOOKUP(AA20,'Name List'!$C$2:$F$98,2,FALSE) -> jg;]Pu; | S20: 5k; tFg;G | T20: 70 | U20: 52 | V20: 30 | W20: 41 | X20: 70 | Y20: 58 | Z20: 19 | AA20: 9 | AB20: 5k; tFg;G
A21: =VLOOKUP(T21,'Name List'!$C$2:$F$98,4,FALSE) -> 41 | B21: =VLOOKUP(T21,'Name List'!$C$2:$F$98,2,FALSE) -> `jP]; | C21: =VLOOKUP(U21,'Name List'!$C$2:$F$98,4,FALSE) -> 31 | D21: =VLOOKUP(U21,'Name List'!$C$2:$F$98,2,FALSE) -> m`;yhf; | E21: =VLOOKUP(V21,'Name List'!$C$2:$F$98,4,FALSE) -> 26 | F21: =VLOOKUP(V21,'Name List'!$C$2:$F$98,2,FALSE) -> ,yf;fzk; | H21: =VLOOKUP(W21,'Name List'!$C$2:$F$98,4,FALSE) -> 39 | I21: =VLOOKUP(W21,'Name List'!$C$2:$F$98,2,FALSE) -> my;Fu;Md; kddk; | J21: =VLOOKUP(X21,'Name List'!$C$2:$F$98,4,FALSE) -> 26 | K21: =VLOOKUP(X21,'Name List'!$C$2:$F$98,2,FALSE) -> gpf;`; | M21: =VLOOKUP(Y21,'Name List'!$C$2:$F$98,4,FALSE) -> 36 | N21: =VLOOKUP(Y21,'Name List'!$C$2:$F$98,2,FALSE) -> jg;]Pu; | O21: =VLOOKUP(Z21,'Name List'!$C$2:$F$98,4,FALSE) -> 31 | P21: =VLOOKUP(Z21,'Name List'!$C$2:$F$98,2,FALSE) -> mfPjh | Q21: =VLOOKUP(AA21,'Name List'!$C$15:$F$108,4,FALSE) -> 39 | R21: =VLOOKUP(AA21,'Name List'!$C$2:$F$98,2,FALSE) -> muGg; ghi\ (,d;\h) | S21: 6k; tFg;G | T21: 20 | U21: 53 | V21: 59 | W21: 6 | X21: 31 | Y21: 10 | Z21: 39 | AA21: 71 | AB21: 6k; tFg;G
A22: =VLOOKUP(T22,'Name List'!$C$2:$F$98,4,FALSE) -> 28 | B22: =VLOOKUP(T22,'Name List'!$C$2:$F$98,2,FALSE) -> jg;]Pu; | C22: =VLOOKUP(U22,'Name List'!$C$2:$F$98,4,FALSE) -> 38 | D22: =VLOOKUP(U22,'Name List'!$C$2:$F$98,2,FALSE) -> kPfhj; | E22: =VLOOKUP(V22,'Name List'!$C$2:$F$98,4,FALSE) -> 31 | F22: =VLOOKUP(V22,'Name List'!$C$2:$F$98,2,FALSE) -> kd;jpf; | H22: =VLOOKUP(W22,'Name List'!$C$2:$F$98,4,FALSE) -> 26 | I22: =VLOOKUP(W22,'Name List'!$C$2:$F$98,2,FALSE) -> ,yf;fzk; | J22: =VLOOKUP(X22,'Name List'!$C$2:$F$98,4,FALSE) -> 28 | K22: =VLOOKUP(X22,'Name List'!$C$2:$F$98,2,FALSE) -> muGg; ghi\ (,d;\h) | M22: =VLOOKUP(Y22,'Name List'!$C$2:$F$98,4,FALSE) -> 41 | N22: =VLOOKUP(Y22,'Name List'!$C$2:$F$98,2,FALSE) -> `jP]; | O22: =VLOOKUP(Z22,'Name List'!$C$2:$F$98,4,FALSE) -> 41 | P22: =VLOOKUP(Z22,'Name List'!$C$2:$F$98,2,FALSE) -> m`;yhf; | Q22: =VLOOKUP(AA22,'Name List'!$C$18:$F$111,4,FALSE) -> 31 | R22: =VLOOKUP(AA22,'Name List'!$C$2:$F$98,2,FALSE) -> gpf;`; | S22: 7k; tFg;G | T22: 11 | U22: 82 | V22: 80 | W22: 60 | X22: 72 | Y22: 21 | Z22: 54 | AA22: 32 | AB22: 7k; tFg;G
A23: my; - ]yh`; muGf; fy;Y}up - NgUtis | S23: Gjd;
A24: =A13 -> ehshe;j ghlNeu ml;ltid - 2026
A25: 8k; ghlk; | C25: 7k; ghlk; | E25: 6k; ghlk; | G25: ifYUyh J}f;fk;> Y`u; njhOif kw;Wk; gfYzT Neuk; 01:45 - 11:30 | H25: 5k; ghlk; | J25: 4k; ghlk; | L25: ,ilNtis 10:10 - 9:55 | M25: 3k; ghlk; | O25: 2k; ghlk; | Q25: 1k; ghlk; | S25: ghl myF | T25: 8 | U25: 7 | V25: 6 | W25: 5 | X25: 4 | Y25: 3 | Z25: 2 | AA25: 1 | AB25: ghl myF
A26: 3:05 -3:45 | C26: 2:25 - 3:05 | E26: 1:45 - 2:25 | H26: 10:50 - 11:30 | J26: 10:10 - 10:50 | M26: 9:05 - 9:55 | O26: 8:25 - 9:05 | Q26: 7:35 - 8:25
A27: =VLOOKUP(T27,'Name List'!$C$2:$F$98,4,FALSE) -> 26 | B27: =VLOOKUP(T27,'Name List'!$C$2:$F$98,2,FALSE) -> ]u;g; (2) | C27: =VLOOKUP(U27,'Name List'!$C$2:$F$98,4,FALSE) -> 28 | D27: =VLOOKUP(U27,'Name List'!$C$2:$F$98,2,FALSE) -> fp]]{d; egpa;aPd; | E27: =VLOOKUP(V27,'Name List'!$C$2:$F$98,4,FALSE) -> 36 | F27: =VLOOKUP(V27,'Name List'!$C$2:$F$98,2,FALSE) -> fypkhJy; Fu;Md; | H27: =VLOOKUP(W27,'Name List'!$C$2:$F$98,4,FALSE) -> 39 | I27: =VLOOKUP(W27,'Name List'!$C$2:$F$98,2,FALSE) -> ,yf;fzk; | J27: =VLOOKUP(X27,'Name List'!$C$2:$F$98,4,FALSE) -> 28 | K27: =VLOOKUP(X27,'Name List'!$C$2:$F$98,2,FALSE) -> fp]]{d; egpa;aPd; | M27: =VLOOKUP(Y27,'Name List'!$C$2:$F$98,4,FALSE) -> 31 | N27: =VLOOKUP(Y27,'Name List'!$C$2:$F$98,2,FALSE) -> muGg; ghi\ (,d;\h) | O27: =VLOOKUP(Z27,'Name List'!$C$2:$F$98,4,FALSE) -> 41 | P27: =VLOOKUP(Z27,'Name List'!$C$2:$F$98,2,FALSE) -> muGg; ghi\( fpuhj;) | Q27: =VLOOKUP(AA27,'Name List'!$C$2:$F$98,4,FALSE) -> 26 | R27: =VLOOKUP(AA27,'Name List'!$C$2:$F$98,2,FALSE) -> ]u;g; (1) | S27: 1k; tFg;G | T27: 94 | U27: 95 | V27: 97 | W27: 96 | X27: 95 | Y27: 63 | Z27: 64 | AA27: 61 | AB27: 1k; tFg;G
A28: =VLOOKUP(T28,'Name List'!$C$2:$F$98,4,FALSE) -> 31 | B28: =VLOOKUP(T28,'Name List'!$C$2:$F$98,2,FALSE) -> gpf;`; | C28: =VLOOKUP(U28,'Name List'!$C$2:$F$98,4,FALSE) -> 41 | D28: =VLOOKUP(U28,'Name List'!$C$2:$F$98,2,FALSE) -> ,yf;fzk; | E28: =VLOOKUP(V28,'Name List'!$C$2:$F$98,4,FALSE) -> 46 | F28: =VLOOKUP(V28,'Name List'!$C$2:$F$98,2,FALSE) -> muGg; ghi\ (,d;\h) | H28: =VLOOKUP(W28,'Name List'!$C$2:$F$98,4,FALSE) -> 44 | I28: =VLOOKUP(W28,'Name List'!$C$2:$F$98,2,FALSE) -> tuyhW | J28: =VLOOKUP(X28,'Name List'!$C$2:$F$98,4,FALSE) -> 36 | K28: =VLOOKUP(X28,'Name List'!$C$2:$F$98,2,FALSE) -> ju;[{kJy; Fu;Md; | M28: =VLOOKUP(Y28,'Name List'!$C$2:$F$98,4,FALSE) -> 44 | N28: =VLOOKUP(Y28,'Name List'!$C$2:$F$98,2,FALSE) -> `jP]; | O28: =VLOOKUP(Z28,'Name List'!$C$2:$F$98,4,FALSE) -> 28 | P28: =VLOOKUP(Z28,'Name List'!$C$2:$F$98,2,FALSE) -> ]u;g; | Q28: =VLOOKUP(AA28,'Name List'!$C$5:$F$99,4,FALSE) -> 44 | R28: =VLOOKUP(AA28,'Name List'!$C$2:$F$98,2,FALSE) -> muGg; ghi\( fpuhj;) | S28: 2k; tFg;G | T28: 27 | U28: 55 | V28: 65 | W28: 43 | X28: 49 | Y28: 16 | Z28: 62 | AA28: 66 | AB28: 2k; tFg;G
A29: =VLOOKUP(T29,'Name List'!$C$2:$F$98,4,FALSE) -> 36 | B29: =VLOOKUP(T29,'Name List'!$C$2:$F$98,2,FALSE) -> m`;yhf; | C29: =VLOOKUP(U29,'Name List'!$C$2:$F$98,4,FALSE) -> 38 | D29: =VLOOKUP(U29,'Name List'!$C$2:$F$98,2,FALSE) -> `jP]; | E29: =VLOOKUP(V29,'Name List'!$C$2:$F$98,4,FALSE) -> 41 | F29: =VLOOKUP(V29,'Name List'!$C$2:$F$98,2,FALSE) -> ju;[{kJy; Fu;Md; | H29: =VLOOKUP(W29,'Name List'!$C$2:$F$98,4,FALSE) -> 28 | I29: =VLOOKUP(W29,'Name List'!$C$2:$F$98,2,FALSE) -> tuyhW | J29: =VLOOKUP(X29,'Name List'!$C$2:$F$98,4,FALSE) -> 41 | K29: =VLOOKUP(X29,'Name List'!$C$2:$F$98,2,FALSE) -> cUJg; ghi\ | M29: =VLOOKUP(Y29,'Name List'!$C$2:$F$98,4,FALSE) -> 38 | N29: =VLOOKUP(Y29,'Name List'!$C$2:$F$98,2,FALSE) -> muGg; ghi\ (,d;\h) | O29: =VLOOKUP(Z29,'Name List'!$C$2:$F$98,4,FALSE) -> 26 | P29: =VLOOKUP(Z29,'Name List'!$C$2:$F$98,2,FALSE) -> gpf;`; | Q29: =VLOOKUP(AA29,'Name List'!$C$8:$F$102,4,FALSE) -> 41 | R29: =VLOOKUP(AA29,'Name List'!$C$2:$F$98,2,FALSE) -> ,yf;fzk; | S29: 3k; tFg;G | T29: 50 | U29: 17 | V29: 91 | W29: 44 | X29: 87 | Y29: 68 | Z29: 28 | AA29: 56 | AB29: 3k; tFg;G
A30: =VLOOKUP(T30,'Name List'!$C$2:$F$98,4,FALSE) -> 46 | B30: =VLOOKUP(T30,'Name List'!$C$2:$F$98,2,FALSE) -> cUJg; ghi\ | C30: =VLOOKUP(U30,'Name List'!$C$2:$F$98,4,FALSE) -> 39 | D30: =VLOOKUP(U30,'Name List'!$C$2:$F$98,2,FALSE) -> m`;yhf; | E30: =VLOOKUP(V30,'Name List'!$C$2:$F$98,4,FALSE) -> 39 | F30: =VLOOKUP(V30,'Name List'!$C$2:$F$98,2,FALSE) -> my;Fu;Md; kddk; | H30: =VLOOKUP(W30,'Name List'!$C$2:$F$98,4,FALSE) -> 31 | I30: =VLOOKUP(W30,'Name List'!$C$2:$F$98,2,FALSE) -> gpf;`; | J30: =VLOOKUP(X30,'Name List'!$C$2:$F$98,4,FALSE) -> 46 | K30: =VLOOKUP(X30,'Name List'!$C$2:$F$98,2,FALSE) -> ,yf;fzk; | M30: =VLOOKUP(Y30,'Name List'!$C$2:$F$98,4,FALSE) -> 46 | N30: =VLOOKUP(Y30,'Name List'!$C$2:$F$98,2,FALSE) -> muGg; ghi\ (,d;\h) | O30: =VLOOKUP(Z30,'Name List'!$C$2:$F$98,4,FALSE) -> 39 | P30: =VLOOKUP(Z30,'Name List'!$C$2:$F$98,2,FALSE) -> jg;]Pu; | Q30: =VLOOKUP(AA30,'Name List'!$C$11:$F$105,4,FALSE) -> 46 | R30: =VLOOKUP(AA30,'Name List'!$C$2:$F$98,2,FALSE) -> `jP]; | S30: 4k; tFg;G | T30: 88 | U30: 51 | V30: 4 | W30: 29 | X30: 57 | Y30: 69 | Z30: 8 | AA30: 18 | AB30: 4k; tFg;G
A31: =VLOOKUP(T31,'Name List'!$C$2:$F$98,4,FALSE) -> 39 | B31: =VLOOKUP(T31,'Name List'!$C$2:$F$98,2,FALSE) -> nrhw;Nfhu;g;Gf; fiy | C31: =VLOOKUP(U31,'Name List'!$C$2:$F$98,4,FALSE) -> 36 | D31: =VLOOKUP(U31,'Name List'!$C$2:$F$98,2,FALSE) -> m`;yhf; | E31: =VLOOKUP(V31,'Name List'!$C$2:$F$98,4,FALSE) -> 28 | F31: =VLOOKUP(V31,'Name List'!$C$2:$F$98,2,FALSE) -> gpf;`; | H31: =VLOOKUP(W31,'Name List'!$C$2:$F$98,4,FALSE) -> 46 | I31: =VLOOKUP(W31,'Name List'!$C$2:$F$98,2,FALSE) -> ,yf;fpak; | J31: =VLOOKUP(X31,'Name List'!$C$2:$F$98,4,FALSE) -> 39 | K31: =VLOOKUP(X31,'Name List'!$C$2:$F$98,2,FALSE) -> muGg; ghi\ (,d;\h) | M31: =VLOOKUP(Y31,'Name List'!$C$2:$F$98,4,FALSE) -> 26 | N31: =VLOOKUP(Y31,'Name List'!$C$2:$F$98,2,FALSE) -> ,yf;fzk; | O31: =VLOOKUP(Z31,'Name List'!$C$2:$F$98,4,FALSE) -> 36 | P31: =VLOOKUP(Z31,'Name List'!$C$2:$F$98,2,FALSE) -> `jP]; | Q31: =VLOOKUP(AA31,'Name List'!$C$15:$F$108,4,FALSE) -> 28 | R31: =VLOOKUP(AA31,'Name List'!$C$2:$F$98,2,FALSE) -> jg;]Pu; | S31: 5k; tFg;G | T31: 76 | U31: 52 | V31: 30 | W31: 73 | X31: 70 | Y31: 58 | Z31: 19 | AA31: 9 | AB31: 5k; tFg;G
A32: =VLOOKUP(T32,'Name List'!$C$2:$F$98,4,FALSE) -> 38 | B32: =VLOOKUP(T32,'Name List'!$C$2:$F$98,2,FALSE) -> ghfg; gpuptpid | C32: =VLOOKUP(U32,'Name List'!$C$2:$F$98,4,FALSE) -> 31 | D32: =VLOOKUP(U32,'Name List'!$C$2:$F$98,2,FALSE) -> m`;yhf; | E32: =VLOOKUP(V32,'Name List'!$C$2:$F$98,4,FALSE) -> 26 | F32: =VLOOKUP(V32,'Name List'!$C$2:$F$98,2,FALSE) -> ,yf;fzk; | H32: =VLOOKUP(W32,'Name List'!$C$2:$F$98,4,FALSE) -> 41 | I32: =VLOOKUP(W32,'Name List'!$C$2:$F$98,2,FALSE) -> `jP]; | J32: =VLOOKUP(X32,'Name List'!$C$2:$F$98,4,FALSE) -> 26 | K32: =VLOOKUP(X32,'Name List'!$C$2:$F$98,2,FALSE) -> gpf;`; | M32: =VLOOKUP(Y32,'Name List'!$C$2:$F$98,4,FALSE) -> 36 | N32: =VLOOKUP(Y32,'Name List'!$C$2:$F$98,2,FALSE) -> jg;]Pu; | O32: =VLOOKUP(Z32,'Name List'!$C$2:$F$98,4,FALSE) -> 31 | P32: =VLOOKUP(Z32,'Name List'!$C$2:$F$98,2,FALSE) -> ,yf;fpak; | Q32: =VLOOKUP(AA32,'Name List'!$C$15:$F$108,4,FALSE) -> 39 | R32: =VLOOKUP(AA32,'Name List'!$C$2:$F$98,2,FALSE) -> nrhw;Nfhu;g;Gf; fiy | S32: 6k; tFg;G | T32: 42 | U32: 53 | V32: 59 | W32: 20 | X32: 31 | Y32: 10 | Z32: 74 | AA32: 77 | AB32: 6k; tFg;G
A33: =VLOOKUP(T33,'Name List'!$C$2:$F$98,4,FALSE) -> 28 | B33: =VLOOKUP(T33,'Name List'!$C$2:$F$98,2,FALSE) -> jg;]Pu; | C33: =VLOOKUP(U33,'Name List'!$C$2:$F$98,4,FALSE) -> 31 | D33: =VLOOKUP(U33,'Name List'!$C$2:$F$98,2,FALSE) -> ,yf;fpak; | E33: =VLOOKUP(V33,'Name List'!$C$2:$F$98,4,FALSE) -> 31 | F33: =VLOOKUP(V33,'Name List'!$C$2:$F$98,2,FALSE) -> mfPjh | H33: =VLOOKUP(W33,'Name List'!$C$2:$F$98,4,FALSE) -> 26 | I33: =VLOOKUP(W33,'Name List'!$C$2:$F$98,2,FALSE) -> ,yf;fzk; | J33: =VLOOKUP(X33,'Name List'!$C$2:$F$98,4,FALSE) -> 28 | K33: =VLOOKUP(X33,'Name List'!$C$2:$F$98,2,FALSE) -> nrhw;Nfhu;g;Gf; fiy | M33: =VLOOKUP(Y33,'Name List'!$C$2:$F$98,4,FALSE) -> 41 | N33: =VLOOKUP(Y33,'Name List'!$C$2:$F$98,2,FALSE) -> `jP]; | O33: =VLOOKUP(Z33,'Name List'!$C$2:$F$98,4,FALSE) -> 41 | P33: =VLOOKUP(Z33,'Name List'!$C$2:$F$98,2,FALSE) -> m`;yhf; | Q33: =VLOOKUP(AA33,'Name List'!$C$18:$F$111,4,FALSE) -> 31 | R33: =VLOOKUP(AA33,'Name List'!$C$2:$F$98,2,FALSE) -> gpf;`; | S33: 7k; tFg;G | T33: 11 | U33: 75 | V33: 40 | W33: 60 | X33: 78 | Y33: 21 | Z33: 54 | AA33: 32 | AB33: 7k; tFg;G

Sheet Mon
A1: my; - ]yh`; muGf; fy;Y}up - NgUtis | T1: jpq;fs;
A2: ='Sun,Tue,Wed'!A24:S24 -> ehshe;j ghlNeu ml;ltid - 2026
A3: 8k; ghlk; | C3: 7k; ghlk; | E3: 6k; ghlk; | G3: ifYUyh J}f;fk;> Y`u; njhOif kw;Wk; gfYzT Neuk; 01:45 - 11:30 | H3: c];jhj;khupd; thuhe;j k\{uh 11:30 - 10:00 | I3: 5k; ghlk; | K3: 4k; ghlk; | M3: وقت صلاة الضحى 10:10 - 9:55 | N3: 3k; ghlk; | P3: 2k; ghlk; | R3: 1k; ghlk; | T3: ghl myF | U3: 8 | V3: 7 | W3: 6 | X3: 5 | Y3: 4 | Z3: 3 | AA3: 2 | AB3: 1 | AC3: الحصص | AE3: 8 | AF3: 7 | AG3: 6 | AH3: 5 | AI3: 4 | AJ3: 3 | AK3: 2 | AL3: 1 | AM3: الحصص
A4: 3:05 -3:45 | C4: 2:25 - 3:05 | E4: 1:45 - 2:25 | I4: 9:30 - 10:00 | K4: 9:00 - 9:30 | N4: 8:30 - 9:00 | P4: 8:00 - 8:30 | R4: 7:30 - 8:00 | AC4: من - إلى | AM4: من - إلى
A5: =VLOOKUP(U5,'Name List'!$C$2:$F$98,4,FALSE) -> 26 | B5: =VLOOKUP(U5,'Name List'!$C$2:$F$98,2,FALSE) -> ]u;g; (2) | C5: =VLOOKUP(V5,'Name List'!$C$2:$F$98,4,FALSE) -> 28 | D5: =VLOOKUP(V5,'Name List'!$C$2:$F$98,2,FALSE) -> muG vOj;jzp | E5: =VLOOKUP(W5,'Name List'!$C$2:$F$98,4,FALSE) -> 36 | F5: =VLOOKUP(W5,'Name List'!$C$2:$F$98,2,FALSE) -> j[;tPj; | I5: =VLOOKUP(X5,'Name List'!$C$2:$F$98,4,FALSE) -> 39 | J5: =VLOOKUP(X5,'Name List'!$C$2:$F$98,2,FALSE) -> ,yf;fzk; | K5: =VLOOKUP(Y5,'Name List'!$C$2:$F$98,4,FALSE) -> 44 | L5: =VLOOKUP(Y5,'Name List'!$C$2:$F$98,2,FALSE) -> gpf;`; | N5: =VLOOKUP(Z5,'Name List'!$C$2:$F$98,4,FALSE) -> 31 | O5: =VLOOKUP(Z5,'Name List'!$C$2:$F$98,2,FALSE) -> muGg; ghi\ (,d;\h) | P5: =VLOOKUP(AA5,'Name List'!$C$2:$F$98,4,FALSE) -> 41 | Q5: =VLOOKUP(AA5,'Name List'!$C$2:$F$98,2,FALSE) -> muGg; ghi\( fpuhj;) | R5: =VLOOKUP(AB5,'Name List'!$C$2:$F$98,4,FALSE) -> 26 | S5: =VLOOKUP(AB5,'Name List'!$C$2:$F$98,2,FALSE) -> ]u;g; (1) | T5: 1k; tFg;G | U5: 94 | V5: 89 | W5: 84 | X5: 96 | Y5: 26 | Z5: 63 | AA5: 64 | AB5: 61 | AC5: الصف الأول | AE5: 1 | AF5: 89 | AG5: 95 | AH5: 26 | AI5: 61 | AJ5: 63 | AK5: 64 | AL5: 61 | AM5: الصف الأول
A6: =VLOOKUP(U6,'Name List'!$C$2:$F$98,4,FALSE) -> 31 | B6: =VLOOKUP(U6,'Name List'!$C$2:$F$98,2,FALSE) -> gpf;`; | C6: =VLOOKUP(V6,'Name List'!$C$2:$F$98,4,FALSE) -> 41 | D6: =VLOOKUP(V6,'Name List'!$C$2:$F$98,2,FALSE) -> ,yf;fzk; | E6: =VLOOKUP(W6,'Name List'!$C$2:$F$98,4,FALSE) -> 46 | F6: =VLOOKUP(W6,'Name List'!$C$2:$F$98,2,FALSE) -> muGg; ghi\ (,d;\h) | I6: =VLOOKUP(X6,'Name List'!$C$2:$F$98,4,FALSE) -> 44 | J6: =VLOOKUP(X6,'Name List'!$C$2:$F$98,2,FALSE) -> j[;tPj; | K6: =VLOOKUP(Y6,'Name List'!$C$2:$F$98,4,FALSE) -> 28 | L6: =VLOOKUP(Y6,'Name List'!$C$2:$F$98,2,FALSE) -> muG vOj;jzp | N6: =VLOOKUP(Z6,'Name List'!$C$2:$F$98,4,FALSE) -> 44 | O6: =VLOOKUP(Z6,'Name List'!$C$2:$F$98,2,FALSE) -> `jP]; | P6: =VLOOKUP(AA6,'Name List'!$C$2:$F$98,4,FALSE) -> 28 | Q6: =VLOOKUP(AA6,'Name List'!$C$2:$F$98,2,FALSE) -> ]u;g; | R6: =VLOOKUP(AB6,'Name List'!$C$5:$F$99,4,FALSE) -> 44 | S6: =VLOOKUP(AB6,'Name List'!$C$2:$F$98,2,FALSE) -> muGg; ghi\( fpuhj;) | T6: 2k; tFg;G | U6: 27 | V6: 55 | W6: 65 | X6: 85 | Y6: 90 | Z6: 16 | AA6: 62 | AB6: 66 | AE6: 43 | AF6: 16 | AG6: 66 | AH6: 27 | AI6: 49 | AJ6: 62 | AK6: 65 | AL6: 55
A7: =VLOOKUP(U7,'Name List'!$C$2:$F$98,4,FALSE) -> 39 | B7: =VLOOKUP(U7,'Name List'!$C$2:$F$98,2,FALSE) -> j[;tPj; | C7: =VLOOKUP(V7,'Name List'!$C$2:$F$98,4,FALSE) -> 38 | D7: =VLOOKUP(V7,'Name List'!$C$2:$F$98,2,FALSE) -> `jP]; | E7: =VLOOKUP(W7,'Name List'!$C$2:$F$98,4,FALSE) -> 41 | F7: =VLOOKUP(W7,'Name List'!$C$2:$F$98,2,FALSE) -> my;Fu;Md; kddk; | I7: =VLOOKUP(X7,'Name List'!$C$2:$F$98,4,FALSE) -> 28 | J7: =VLOOKUP(X7,'Name List'!$C$2:$F$98,2,FALSE) -> mfPjh | K7: =VLOOKUP(Y7,'Name List'!$C$2:$F$98,4,FALSE) -> 41 | L7: =VLOOKUP(Y7,'Name List'!$C$2:$F$98,2,FALSE) -> cUJg; ghi\ | N7: =VLOOKUP(Z7,'Name List'!$C$2:$F$98,4,FALSE) -> 38 | O7: =VLOOKUP(Z7,'Name List'!$C$2:$F$98,2,FALSE) -> muGg; ghi\ (,d;\h) | P7: =VLOOKUP(AA7,'Name List'!$C$2:$F$98,4,FALSE) -> 26 | Q7: =VLOOKUP(AA7,'Name List'!$C$2:$F$98,2,FALSE) -> gpf;`; | R7: =VLOOKUP(AB7,'Name List'!$C$8:$F$102,4,FALSE) -> 41 | S7: =VLOOKUP(AB7,'Name List'!$C$2:$F$98,2,FALSE) -> ,yf;fzk; | T7: 3k; tFg;G | U7: 86 | V7: 17 | W7: 3 | X7: 36 | Y7: 87 | Z7: 68 | AA7: 28 | AB7: 56 | AE7: 87 | AF7: 36 | AG7: 91 | AH7: 56 | AI7: 17 | AJ7: 67 | AK7: 50 | AL7: 28
A8: =VLOOKUP(U8,'Name List'!$C$2:$F$98,4,FALSE) -> 46 | B8: =VLOOKUP(U8,'Name List'!$C$2:$F$98,2,FALSE) -> cUJg; ghi\ | C8: =VLOOKUP(V8,'Name List'!$C$2:$F$98,4,FALSE) -> 36 | D8: =VLOOKUP(V8,'Name List'!$C$2:$F$98,2,FALSE) -> tuyhW | E8: =VLOOKUP(W8,'Name List'!$C$2:$F$98,4,FALSE) -> 38 | F8: =VLOOKUP(W8,'Name List'!$C$2:$F$98,2,FALSE) -> mfPjh | I8: =VLOOKUP(X8,'Name List'!$C$2:$F$98,4,FALSE) -> 31 | J8: =VLOOKUP(X8,'Name List'!$C$2:$F$98,2,FALSE) -> gpf;`; | K8: =VLOOKUP(Y8,'Name List'!$C$2:$F$98,4,FALSE) -> 46 | L8: =VLOOKUP(Y8,'Name List'!$C$2:$F$98,2,FALSE) -> ,yf;fzk; | N8: =VLOOKUP(Z8,'Name List'!$C$2:$F$98,4,FALSE) -> 46 | O8: =VLOOKUP(Z8,'Name List'!$C$2:$F$98,2,FALSE) -> muGg; ghi\ (,d;\h) | P8: =VLOOKUP(AA8,'Name List'!$C$2:$F$98,4,FALSE) -> 39 | Q8: =VLOOKUP(AA8,'Name List'!$C$2:$F$98,2,FALSE) -> jg;]Pu; | R8: =VLOOKUP(AB8,'Name List'!$C$11:$F$105,4,FALSE) -> 46 | S8: =VLOOKUP(AB8,'Name List'!$C$2:$F$98,2,FALSE) -> `jP]; | T8: 4k; tFg;G | U8: 88 | V8: 45 | W8: 37 | X8: 29 | Y8: 57 | Z8: 69 | AA8: 8 | AB8: 18 | AE8: 45 | AF8: 4 | AG8: 88 | AH8: 18 | AI8: 8 | AJ8: 29 | AK8: 69 | AL8: 57
A9: =VLOOKUP(U9,'Name List'!$C$2:$F$98,4,FALSE) -> 36 | B9: =VLOOKUP(U9,'Name List'!$C$2:$F$98,2,FALSE) -> tuyhW | C9: =VLOOKUP(V9,'Name List'!$C$2:$F$98,4,FALSE) -> 31 | D9: =VLOOKUP(V9,'Name List'!$C$2:$F$98,2,FALSE) -> mfPjh | E9: =VLOOKUP(W9,'Name List'!$C$2:$F$98,4,FALSE) -> 28 | F9: =VLOOKUP(W9,'Name List'!$C$2:$F$98,2,FALSE) -> gpf;`; | I9: =VLOOKUP(X9,'Name List'!$C$2:$F$98,4,FALSE) -> 38 | J9: =VLOOKUP(X9,'Name List'!$C$2:$F$98,2,FALSE) -> ghfg; gpuptpid | K9: =VLOOKUP(Y9,'Name List'!$C$2:$F$98,4,FALSE) -> 39 | L9: =VLOOKUP(Y9,'Name List'!$C$2:$F$98,2,FALSE) -> muGg; ghi\ (,d;\h) | N9: =VLOOKUP(Z9,'Name List'!$C$2:$F$98,4,FALSE) -> 26 | O9: =VLOOKUP(Z9,'Name List'!$C$2:$F$98,2,FALSE) -> ,yf;fzk; | P9: =VLOOKUP(AA9,'Name List'!$C$2:$F$98,4,FALSE) -> 36 | Q9: =VLOOKUP(AA9,'Name List'!$C$2:$F$98,2,FALSE) -> `jP]; | R9: =VLOOKUP(AB9,'Name List'!$C$15:$F$108,4,FALSE) -> 28 | S9: =VLOOKUP(AB9,'Name List'!$C$2:$F$98,2,FALSE) -> jg;]Pu; | T9: 5k; tFg;G | U9: 46 | V9: 38 | W9: 30 | X9: 41 | Y9: 70 | Z9: 58 | AA9: 19 | AB9: 9 | AE9: 38 | AF9: 46 | AG9: 73 | AH9: 19 | AI9: 30 | AJ9: 70 | AK9: 58 | AL9: 9
A10: =VLOOKUP(U10,'Name List'!$C$2:$F$98,4,FALSE) -> 41 | B10: =VLOOKUP(U10,'Name List'!$C$2:$F$98,2,FALSE) -> c]{Yy; `jP]; | C10: =VLOOKUP(V10,'Name List'!$C$2:$F$98,4,FALSE) -> 46 | D10: =VLOOKUP(V10,'Name List'!$C$2:$F$98,2,FALSE) -> mj;ahd; | E10: =VLOOKUP(W10,'Name List'!$C$2:$F$98,4,FALSE) -> 26 | F10: =VLOOKUP(W10,'Name List'!$C$2:$F$98,2,FALSE) -> ,yf;fzk; | I10: =VLOOKUP(X10,'Name List'!$C$2:$F$98,4,FALSE) -> 36 | J10: =VLOOKUP(X10,'Name List'!$C$2:$F$98,2,FALSE) -> tuyhW | K10: =VLOOKUP(Y10,'Name List'!$C$2:$F$98,4,FALSE) -> 26 | L10: =VLOOKUP(Y10,'Name List'!$C$2:$F$98,2,FALSE) -> gpf;`; | N10: =VLOOKUP(Z10,'Name List'!$C$2:$F$98,4,FALSE) -> 36 | O10: =VLOOKUP(Z10,'Name List'!$C$2:$F$98,2,FALSE) -> jg;]Pu; | P10: =VLOOKUP(AA10,'Name List'!$C$2:$F$98,4,FALSE) -> 31 | Q10: =VLOOKUP(AA10,'Name List'!$C$2:$F$98,2,FALSE) -> mfPjh | R10: =VLOOKUP(AB10,'Name List'!$C$15:$F$108,4,FALSE) -> 39 | S10: =VLOOKUP(AB10,'Name List'!$C$2:$F$98,2,FALSE) -> muGg; ghi\ (,d;\h) | T10: 6k; tFg;G | U10: 24 | V10: 81 | W10: 59 | X10: 47 | Y10: 31 | Z10: 10 | AA10: 39 | AB10: 71
A11: =VLOOKUP(U11,'Name List'!$C$2:$F$98,4,FALSE) -> 28 | B11: =VLOOKUP(U11,'Name List'!$C$2:$F$98,2,FALSE) -> jg;]Pu; | C11: =VLOOKUP(V11,'Name List'!$C$2:$F$98,4,FALSE) -> 38 | D11: =VLOOKUP(V11,'Name List'!$C$2:$F$98,2,FALSE) -> kPfhj; | E11: =VLOOKUP(W11,'Name List'!$C$2:$F$98,4,FALSE) -> 31 | F11: =VLOOKUP(W11,'Name List'!$C$2:$F$98,2,FALSE) -> gpuf; | I11: =VLOOKUP(X11,'Name List'!$C$2:$F$98,4,FALSE) -> 26 | J11: =VLOOKUP(X11,'Name List'!$C$2:$F$98,2,FALSE) -> ,yf;fzk; | K11: =VLOOKUP(Y11,'Name List'!$C$2:$F$98,4,FALSE) -> 28 | L11: =VLOOKUP(Y11,'Name List'!$C$2:$F$98,2,FALSE) -> muGg; ghi\ (,d;\h) | N11: =VLOOKUP(Z11,'Name List'!$C$2:$F$98,4,FALSE) -> 41 | O11: =VLOOKUP(Z11,'Name List'!$C$2:$F$98,2,FALSE) -> `jP]; | P11: =VLOOKUP(AA11,'Name List'!$C$2:$F$98,4,FALSE) -> 41 | Q11: =VLOOKUP(AA11,'Name List'!$C$2:$F$98,2,FALSE) -> tuyhW | R11: =VLOOKUP(AB11,'Name List'!$C$18:$F$111,4,FALSE) -> 31 | S11: =VLOOKUP(AB11,'Name List'!$C$2:$F$98,2,FALSE) -> gpf;`; | T11: 7k; tFg;G | U11: 11 | V11: 82 | W11: 83 | X11: 60 | Y11: 72 | Z11: 21 | AA11: 48 | AB11: 32 | AE11: 54 | AF11: 82 | AG11: 75 | AH11: 72 | AI11: 21 | AJ11: 32 | AK11: 60 | AL11: 11

Sheet thu
A1: my; - ]yh`; muGf; fy;Y}up - NgUtis | V1: tpahod;
A2: =Mon!A2 -> ehshe;j ghlNeu ml;ltid - 2026
A3: 8k; ghlk; | C3: 7k; ghlk; | E3: 6k; ghlk; | G3: وقت القيلولة و صلاة الظهر والغذاء 01:45 - 11:30 | H3: المشورة الأسبوعية للأساتذة 11:30 - 10:00 | I3: 5k; ghlk; | K3: 4k; ghlk; | M3: وقت صلاة الضحى 10:10 - 9:55 | N3: 10:00 - 8:30 khztu; kd;wk; | O3: 8:20 - 8:00 fhiy rhg;ghl;L Neuk; | P3: 3k; ghlk; | R3: 2k; ghlk; | T3: 1k; ghlk; | V3: ghl myF | W3: 8 | X3: 7 | Y3: 6 | Z3: 5 | AA3: 4 | AB3: 3 | AC3: 2 | AD3: 1 | AE3: الحصص | AG3: 8 | AH3: 7 | AI3: 6 | AJ3: 5 | AK3: 4 | AL3: 3 | AM3: 2 | AN3: 1 | AO3: الحصص
A4: 12:15 - 12:45 | C4: 11:45 - 12:15 | E4: 11:15 - 11:45 | I4: 10:45 - 11:15 | K4: 10:15 - 10:45 | P4: 7:30 - 8:00 | R4: 7:00 - 7:30 | T4: 6:30 - 7:00 | AE4: من - إلى | AO4: من - إلى
A5: =VLOOKUP(W5,'Name List'!$C$2:$F$98,4,FALSE) -> 26 | B5: =VLOOKUP(W5,'Name List'!$C$2:$F$98,2,FALSE) -> ]u;g; (2) | C5: =VLOOKUP(X5,'Name List'!$C$2:$F$98,4,FALSE) -> 28 | D5: =VLOOKUP(X5,'Name List'!$C$2:$F$98,2,FALSE) -> fp]]{d; egpa;aPd; | E5: =VLOOKUP(Y5,'Name List'!$C$2:$F$98,4,FALSE) -> 36 | F5: =VLOOKUP(Y5,'Name List'!$C$2:$F$98,2,FALSE) -> my;Fu;Md; kddk; | I5: =VLOOKUP(Z5,'Name List'!$C$2:$F$98,4,FALSE) -> 39 | J5: =VLOOKUP(Z5,'Name List'!$C$2:$F$98,2,FALSE) -> ,yf;fzk; | K5: =VLOOKUP(AA5,'Name List'!$C$2:$F$98,4,FALSE) -> 28 | L5: =VLOOKUP(AA5,'Name List'!$C$2:$F$98,2,FALSE) -> fp]]{d; egpa;aPd; | P5: =VLOOKUP(AB5,'Name List'!$C$2:$F$98,4,FALSE) -> 31 | Q5: =VLOOKUP(AB5,'Name List'!$C$2:$F$98,2,FALSE) -> muGg; ghi\ (,d;\h) | R5: =VLOOKUP(AC5,'Name List'!$C$2:$F$98,4,FALSE) -> 41 | S5: =VLOOKUP(AC5,'Name List'!$C$2:$F$98,2,FALSE) -> muGg; ghi\( fpuhj;) | T5: =VLOOKUP(AD5,'Name List'!$C$2:$F$98,4,FALSE) -> 26 | U5: =VLOOKUP(AD5,'Name List'!$C$2:$F$98,2,FALSE) -> ]u;g; (1) | V5: 1k; tFg;G | W5: 94 | X5: 95 | Y5: 1 | Z5: 96 | AA5: 95 | AB5: 63 | AC5: 64 | AD5: 61 | AE5: الصف الأول | AG5: 84 | AH5: 89 | AI5: 95 | AJ5: 61 | AK5: 26 | AL5: 63 | AM5: 64 | AN5: 61 | AO5: الصف الأول
A6: =VLOOKUP(W6,'Name List'!$C$2:$F$98,4,FALSE) -> 31 | B6: =VLOOKUP(W6,'Name List'!$C$2:$F$98,2,FALSE) -> gpf;`; | C6: =VLOOKUP(X6,'Name List'!$C$2:$F$98,4,FALSE) -> 41 | D6: =VLOOKUP(X6,'Name List'!$C$2:$F$98,2,FALSE) -> ,yf;fzk; | E6: =VLOOKUP(Y6,'Name List'!$C$2:$F$98,4,FALSE) -> 46 | F6: =VLOOKUP(Y6,'Name List'!$C$2:$F$98,2,FALSE) -> muGg; ghi\ (,d;\h) | I6: =VLOOKUP(Z6,'Name List'!$C$2:$F$98,4,FALSE) -> 44 | J6: =VLOOKUP(Z6,'Name List'!$C$2:$F$98,2,FALSE) -> tuyhW | K6: =VLOOKUP(AA6,'Name List'!$C$2:$F$98,4,FALSE) -> 36 | L6: =VLOOKUP(AA6,'Name List'!$C$2:$F$98,2,FALSE) -> ju;[{kJy; Fu;Md; | P6: =VLOOKUP(AB6,'Name List'!$C$2:$F$98,4,FALSE) -> 44 | Q6: =VLOOKUP(AB6,'Name List'!$C$2:$F$98,2,FALSE) -> `jP]; | R6: =VLOOKUP(AC6,'Name List'!$C$2:$F$98,4,FALSE) -> 28 | S6: =VLOOKUP(AC6,'Name List'!$C$2:$F$98,2,FALSE) -> ]u;g; | T6: =VLOOKUP(AD6,'Name List'!$C$5:$F$99,4,FALSE) -> 44 | U6: =VLOOKUP(AD6,'Name List'!$C$2:$F$98,2,FALSE) -> muGg; ghi\( fpuhj;) | V6: 2k; tFg;G | W6: 27 | X6: 55 | Y6: 65 | Z6: 43 | AA6: 49 | AB6: 16 | AC6: 62 | AD6: 66 | AG6: 90 | AH6: 16 | AI6: 66 | AJ6: 85 | AK6: 27 | AL6: 62 | AM6: 55 | AN6: 65
A7: =VLOOKUP(W7,'Name List'!$C$2:$F$98,4,FALSE) -> 36 | B7: =VLOOKUP(W7,'Name List'!$C$2:$F$98,2,FALSE) -> m`;yhf; | C7: =VLOOKUP(X7,'Name List'!$C$2:$F$98,4,FALSE) -> 38 | D7: =VLOOKUP(X7,'Name List'!$C$2:$F$98,2,FALSE) -> `jP]; | E7: =VLOOKUP(Y7,'Name List'!$C$2:$F$98,4,FALSE) -> 41 | F7: =VLOOKUP(Y7,'Name List'!$C$2:$F$98,2,FALSE) -> ju;[{kJy; Fu;Md; | I7: =VLOOKUP(Z7,'Name List'!$C$2:$F$98,4,FALSE) -> 28 | J7: =VLOOKUP(Z7,'Name List'!$C$2:$F$98,2,FALSE) -> tuyhW | K7: =VLOOKUP(AA7,'Name List'!$C$2:$F$98,4,FALSE) -> 41 | L7: =VLOOKUP(AA7,'Name List'!$C$2:$F$98,2,FALSE) -> cUJg; ghi\ | P7: =VLOOKUP(AB7,'Name List'!$C$2:$F$98,4,FALSE) -> 38 | Q7: =VLOOKUP(AB7,'Name List'!$C$2:$F$98,2,FALSE) -> muGg; ghi\ (,d;\h) | R7: =VLOOKUP(AC7,'Name List'!$C$2:$F$98,4,FALSE) -> 26 | S7: =VLOOKUP(AC7,'Name List'!$C$2:$F$98,2,FALSE) -> gpf;`; | T7: =VLOOKUP(AD7,'Name List'!$C$8:$F$102,4,FALSE) -> 41 | U7: =VLOOKUP(AD7,'Name List'!$C$2:$F$98,2,FALSE) -> ,yf;fzk; | V7: 3k; tFg;G | W7: 50 | X7: 17 | Y7: 91 | Z7: 44 | AA7: 87 | AB7: 68 | AC7: 28 | AD7: 56 | AG7: 87 | AH7: 86 | AI7: 44 | AJ7: 67 | AK7: 56 | AL7: 17 | AM7: 3 | AN7: 28
A8: =VLOOKUP(W8,'Name List'!$C$2:$F$98,4,FALSE) -> 46 | B8: =VLOOKUP(W8,'Name List'!$C$2:$F$98,2,FALSE) -> cUJg; ghi\ | C8: =VLOOKUP(X8,'Name List'!$C$2:$F$98,4,FALSE) -> 39 | D8: =VLOOKUP(X8,'Name List'!$C$2:$F$98,2,FALSE) -> m`;yhf; | E8: =VLOOKUP(Y8,'Name List'!$C$2:$F$98,4,FALSE) -> 39 | F8: =VLOOKUP(Y8,'Name List'!$C$2:$F$98,2,FALSE) -> my;Fu;Md; kddk; | I8: =VLOOKUP(Z8,'Name List'!$C$2:$F$98,4,FALSE) -> 31 | J8: =VLOOKUP(Z8,'Name List'!$C$2:$F$98,2,FALSE) -> gpf;`; | K8: =VLOOKUP(AA8,'Name List'!$C$2:$F$98,4,FALSE) -> 46 | L8: =VLOOKUP(AA8,'Name List'!$C$2:$F$98,2,FALSE) -> ,yf;fzk; | P8: =VLOOKUP(AB8,'Name List'!$C$2:$F$98,4,FALSE) -> 46 | Q8: =VLOOKUP(AB8,'Name List'!$C$2:$F$98,2,FALSE) -> muGg; ghi\ (,d;\h) | R8: =VLOOKUP(AC8,'Name List'!$C$2:$F$98,4,FALSE) -> 39 | S8: =VLOOKUP(AC8,'Name List'!$C$2:$F$98,2,FALSE) -> c]{Yj; jg;]Pu; | T8: =VLOOKUP(AD8,'Name List'!$C$11:$F$105,4,FALSE) -> 46 | U8: =VLOOKUP(AD8,'Name List'!$C$2:$F$98,2,FALSE) -> c]{Yy; `jP]; | V8: 4k; tFg;G | W8: 88 | X8: 51 | Y8: 4 | Z8: 29 | AA8: 57 | AB8: 69 | AC8: 12 | AD8: 22 | AG8: 51 | AH8: 37 | AI8: 88 | AJ8: 12 | AK8: 22 | AL8: 29 | AM8: 69 | AN8: 57
A9: =VLOOKUP(W9,'Name List'!$C$2:$F$98,4,FALSE) -> 39 | B9: =VLOOKUP(W9,'Name List'!$C$2:$F$98,2,FALSE) -> nrhw;Nfhu;g;Gf; fiy | C9: =VLOOKUP(X9,'Name List'!$C$2:$F$98,4,FALSE) -> 36 | D9: =VLOOKUP(X9,'Name List'!$C$2:$F$98,2,FALSE) -> m`;yhf; | E9: =VLOOKUP(Y9,'Name List'!$C$2:$F$98,4,FALSE) -> 28 | F9: =VLOOKUP(Y9,'Name List'!$C$2:$F$98,2,FALSE) -> c]{Yy; gpf;`; | I9: =VLOOKUP(Z9,'Name List'!$C$2:$F$98,4,FALSE) -> 46 | J9: =VLOOKUP(Z9,'Name List'!$C$2:$F$98,2,FALSE) -> ,yf;fpak; | K9: =VLOOKUP(AA9,'Name List'!$C$2:$F$98,4,FALSE) -> 39 | L9: =VLOOKUP(AA9,'Name List'!$C$2:$F$98,2,FALSE) -> muGg; ghi\ (,d;\h) | P9: =VLOOKUP(AB9,'Name List'!$C$2:$F$98,4,FALSE) -> 26 | Q9: =VLOOKUP(AB9,'Name List'!$C$2:$F$98,2,FALSE) -> ,yf;fzk; | R9: =VLOOKUP(AC9,'Name List'!$C$2:$F$98,4,FALSE) -> 36 | S9: =VLOOKUP(AC9,'Name List'!$C$2:$F$98,2,FALSE) -> c]{Yy; `jP]; | T9: =VLOOKUP(AD9,'Name List'!$C$15:$F$108,4,FALSE) -> 28 | U9: =VLOOKUP(AD9,'Name List'!$C$2:$F$98,2,FALSE) -> c]{Yj; jg;]Pu; | V9: 5k; tFg;G | W9: 76 | X9: 52 | Y9: 33 | Z9: 73 | AA9: 70 | AB9: 58 | AC9: 23 | AD9: 13 | AG9: 41 | AH9: 52 | AI9: 76 | AJ9: 23 | AK9: 33 | AL9: 70 | AM9: 58 | AN9: 13
A10: =VLOOKUP(W10,'Name List'!$C$2:$F$98,4,FALSE) -> 38 | B10: =VLOOKUP(W10,'Name List'!$C$2:$F$98,2,FALSE) -> ghfg; gpuptpid | C10: =VLOOKUP(X10,'Name List'!$C$2:$F$98,4,FALSE) -> 31 | D10: =VLOOKUP(X10,'Name List'!$C$2:$F$98,2,FALSE) -> kd;jpf; | E10: =VLOOKUP(Y10,'Name List'!$C$2:$F$98,4,FALSE) -> 26 | F10: =VLOOKUP(Y10,'Name List'!$C$2:$F$98,2,FALSE) -> ,yf;fzk; | I10: =VLOOKUP(Z10,'Name List'!$C$2:$F$98,4,FALSE) -> 36 | J10: =VLOOKUP(Z10,'Name List'!$C$2:$F$98,2,FALSE) -> tuyhW | K10: =VLOOKUP(AA10,'Name List'!$C$2:$F$98,4,FALSE) -> 26 | L10: =VLOOKUP(AA10,'Name List'!$C$2:$F$98,2,FALSE) -> c]{Yy; gpf;`; | P10: =VLOOKUP(AB10,'Name List'!$C$2:$F$98,4,FALSE) -> 36 | Q10: =VLOOKUP(AB10,'Name List'!$C$2:$F$98,2,FALSE) -> c]{Yj; jg;]Pu; | R10: =VLOOKUP(AC10,'Name List'!$C$2:$F$98,4,FALSE) -> 31 | S10: =VLOOKUP(AC10,'Name List'!$C$2:$F$98,2,FALSE) -> ,yf;fpak; | T10: =VLOOKUP(AD10,'Name List'!$C$15:$F$108,4,FALSE) -> 39 | U10: =VLOOKUP(AD10,'Name List'!$C$2:$F$98,2,FALSE) -> nrhw;Nfhu;g;Gf; fiy | V10: 6k; tFg;G | W10: 42 | X10: 79 | Y10: 59 | Z10: 47 | AA10: 34 | AB10: 14 | AC10: 74 | AD10: 77
A11: =VLOOKUP(W11,'Name List'!$C$2:$F$98,4,FALSE) -> 28 | B11: =VLOOKUP(W11,'Name List'!$C$2:$F$98,2,FALSE) -> c]{Yj; jg;]Pu; | C11: =VLOOKUP(X11,'Name List'!$C$2:$F$98,4,FALSE) -> 31 | D11: =VLOOKUP(X11,'Name List'!$C$2:$F$98,2,FALSE) -> ,yf;fpak; | E11: =VLOOKUP(Y11,'Name List'!$C$2:$F$98,4,FALSE) -> 31 | F11: =VLOOKUP(Y11,'Name List'!$C$2:$F$98,2,FALSE) -> mfPjh | I11: =VLOOKUP(Z11,'Name List'!$C$2:$F$98,4,FALSE) -> 26 | J11: =VLOOKUP(Z11,'Name List'!$C$2:$F$98,2,FALSE) -> ,yf;fzk; | K11: =VLOOKUP(AA11,'Name List'!$C$2:$F$98,4,FALSE) -> 28 | L11: =VLOOKUP(AA11,'Name List'!$C$2:$F$98,2,FALSE) -> nrhw;Nfhu;g;Gf; fiy | P11: =VLOOKUP(AB11,'Name List'!$C$2:$F$98,4,FALSE) -> 41 | Q11: =VLOOKUP(AB11,'Name List'!$C$2:$F$98,2,FALSE) -> c]{Yy; `jP]; | R11: =VLOOKUP(AC11,'Name List'!$C$2:$F$98,4,FALSE) -> 41 | S11: =VLOOKUP(AC11,'Name List'!$C$2:$F$98,2,FALSE) -> my;Fu;Md; kddk; | T11: =VLOOKUP(AD11,'Name List'!$C$18:$F$111,4,FALSE) -> 31 | U11: =VLOOKUP(AD11,'Name List'!$C$2:$F$98,2,FALSE) -> c]{Yy; gpf;`; | V11: 7k; tFg;G | W11: 15 | X11: 75 | Y11: 40 | Z11: 60 | AA11: 78 | AB11: 25 | AC11: 7 | AD11: 35 | AG11: 40 | AH11: 80 | AI11: 48 | AJ11: 78 | AK11: 25 | AL11: 35 | AM11: 60 | AN11: 15

Sheet Name List
B1: Class | C1: S/R No: | E1: subject | F1: Usthadh | N1: subject
B2: 1 | C2: 1 | D2: my;Fu;Md; kddk; | E2: my;Fu;Md; kddk; | F2: 36 | H2: 2 | I2: m\;n\a;`; - ,u;\hj; | J2: ASH-SHAIKH M.S.M IRSHAD | K2: =H2 -> 2 | L2: الشيخ إرشاد (الرباني) | N2: تحفيظ القرآن
B3: 1 | C3: 26 | D3: gpf;`; | E3: gpf;`; | F3: 44 | H3: 1 | I3: m\;n\a;`; - K`k;kj; | J3: ASH-SHAIKH S.M. MUHAMMEDH | K3: =H3 -> 1 | L3: الشيخ محمد (الرشادي) | N3: علم الفقه
B4: 1 | C4: 61 | D4: ]u;g; (1) | E4: ]u;g; (1) | F4: 26 | H4: 3 | I4: m\;n\a;`; - ghap]Pd; | J4: ASH-SHAIKH M.R.M. FAYIZEEN | K4: =H4 -> 3 | L4: الشيخ فائزين (النووي) | N4: علم الصرف (1)
B5: 1 | C5: 63 | D5: muGg; ghi\ (,d;\h) | E5: muGg; ghi\ (,d;\h) | F5: 31 | H5: 4 | I5: m\;n\a;`; - `u;]hd; | J5: ASH-SHAIKH S.H.M. HARSAN | K5: =H5 -> 4 | L5: الشيخ حرثان (الرشادي) | N5: علم اللغة العربية (الإنشاء)
B6: 1 | C6: 64 | D6: muGg; ghi\( fpuhj;) | E6: muGg; ghi\ ( fpuhj;) | F6: 41 | H6: 5 | I6: m\;n\a;`; - ,];]j; | J6: ASH-SHAIKH K.M.IZZATH | K6: =H6 -> 5 | L6: الشيخ عزة (الإحساني) | N6: علم اللغة العربية (القراءة)
B7: 1 | C7: 84 | D7: j[;tPj; | E7: j[;tPj; | F7: 36 | H7: 6 | I7: m\;n\a;`; - ,y;`hk; | J7: ASH-SHAIKH M.J.M. ILHAM | K7: =H7 -> 6 | L7: الشيخ إلهام (الرشادي) | N7: علم التجويد
B8: 1 | C8: 95 | D8: fp]]{d; egpa;aPd; | E8: fp]]{d; egpa;aPd; | F8: 28 | H8: 7 | I8: m\;n\a;`; - ,`;jp\hk; | J8: ASH-SHAIKH M.S.M.IHTHISAM | K8: =H8 -> 7 | L8: الشيخ احتشام الحسن (الباري) | N8: قصص النبين (1,2)
B9: 1 | C9: 89 | D9: muG vOj;jzp | E9: muG vOj;jzp | F9: 28 | H9: 8 | I9: m\;n\a;`; - ig&]; | J9: ASH-SHAIKH I.M.FAIROOS | K9: =H9 -> 8 | L9: الشيخ فيروز (الصلاحي) | N9: الخط العربي
B10: 1 | C10: 94 | D10: ]u;g; (2) | E10: ]u;g; (2) | F10: 26 | H10: 9 | I10: m\;n\a;`; - \`Pu; m`;kj; | J10: ASH-SHAIKH M.S.SHAHEER AHMAD | K10: =H10 -> 9 | L10: الشيخ شهير أحمد (الصلاحي) | N10: علم الصرف (2)
B11: 1 | C11: 96 | D11: ,yf;fzk; | E11: ,yf;fzk; | F11: 39 | H11: 10 | I11: m\;n\a;`; - md;]g; | J11: ASH-SHAIKH M.H.M.ANSAF | K11: =H11 -> 10 | L11: الشيخ أنصف (الرشادي) | N11: علم النحو
B12: 1 | C12: 97 | D12: fypkhJy; Fu;Md; | E12: fypkhJy; Fu;Md; | F12: 36 | H12: 11 | I12: m\;n\a;`; - ,f;uhk; | J12: ASH-SHAIKH M.S.M. IKRAM | K12: =H12 -> 11 | L12: الشيخ إكرام (الصلاحي) | N12: كلمات القرآن
B13: 2 | C13: 2 | D13: my;Fu;Md; kddk; | E13: my;Fu;Md; kddk; | F13: 28 | H13: 12 | I13: m\;n\a;`; - ekP]; | J13: ASH-SHAIKH M.M.NAMEES | K13: =H13 -> 12 | L13: الشيخ نميس (الإحساني) | N13: تحفيظ القرآن
... B15: 2 | C15: 27 | D15: gpf;`; | E15: gpf;`; | F15: 31 | H15: 14 | I15: m\;n\a;`; - mg;Jy;yh`; | J15: ASH-SHAIKH A.R.ABDULLAH | K15: =H15 -> 14 | L15: الشيخ عبد الله (الصلاحي) | N15: علم الفقه
B16: 2 | C16: 43 | D16: tuyhW | E16: tuyhW | F16: 44 | N16: التاريخ الإسلامي
B17: 2 | C17: 49 | D17: ju;[{kJy; Fu;Md; | E17: ju;[{kJy; Fu;Md; | F17: 36 | N17: ترجمة القرآن
B18: 2 | C18: 55 | D18: ,yf;fzk; | E18: ,yf;fzk; | F18: 41 | N18: علم النحو
B19: 2 | C19: 62 | D19: ]u;g; | E19: ]u;g; | F19: 28 | I19: الشيخ إرشاد (الرباني) | N19: علم الصرف
B20: 2 | C20: 65 | D20: muGg; ghi\ (,d;\h) | E20: muGg; ghi\ (,d;\h) | F20: 46 | I20: الشيخ محمد (الرشادي) | N20: علم اللغة العربية (الإنشاء)
B21: 2 | C21: 66 | D21: muGg; ghi\( fpuhj;) | E21: muGg; ghi\ ( fpuhj;) | F21: 44 | I21: الشيخ فائزين (النووي) | N21: علم اللغة العربية (القراءة)
B22: 2 | C22: 85 | D22: j[;tPj; | E22: j[;tPj; | F22: 44 | I22: الشيخ حرثان (الرشادي) | N22: علم التجويد
B23: 2 | C23: 90 | D23: muG vOj;jzp | E23: muG vOj;jzp | F23: 28 | I23: الشيخ عزة (الإحساني) | N23: الخط العربي
B24: 2 | C24: 92 | D24: muGg; ghi\( fpuhj;) | E24: muGg; ghi\( fpuhj;) | F24: 44 | I24: الشيخ إلهام (الرشادي) | N24: علم اللغة العربية (القراءة)
B25: 3 | C25: 3 | D25: my;Fu;Md; kddk; | E25: my;Fu;Md; kddk; | F25: 41 | I25: الشيخ احتشام الحسن (الباري) | N25: تحفيظ القرآن
B26: 3 | C26: 17 | D26: `jP]; | E26: `jP]; | F26: 38 | I26: الشيخ فيروز (الصلاحي) | N26: علم الحديث الشريف
B27: 3 | C27: 28 | D27: gpf;`; | E27: gpf;`; | F27: 26 | I27: الشيخ شهير أحمد (الصلاحي) | N27: علم الفقه
B28: 3 | C28: 36 | D28: mfPjh | E28: mfPjh | F28: 28 | I28: الشيخ أنصف (الرشادي) | N28: علم العقيدة
B29: 3 | C29: 44 | D29: tuyhW | E29: tuyhW | F29: 28 | I29: الشيخ إكرام (الصلاحي) | N29: التاريخ الإسلامي
B30: 3 | C30: 50 | D30: m`;yhf; | E30: m`;yhf; | F30: 36 | I30: الشيخ نميس (الإحساني) | N30: علم الأخلاق
B31: 3 | C31: 56 | D31: ,yf;fzk; | E31: ,yf;fzk; | F31: 41 | I31: الشيخ أنفس (الصلاحي) | N31: علم النحو
B32: 3 | C32: 67 | D32: muGg; ghi\( fpuhj;) | E32: muGg; ghi\( fpuhj;) | F32: 38 | N32: علم اللغة العربية (القراءة)
B33: 3 | C33: 68 | D33: muGg; ghi\ (,d;\h) | E33: muGg; ghi\ (,d;\h) | F33: 38 | N33: علم اللغة العربية (الإنشاء)
B34: 3 | C34: 86 | D34: j[;tPj; | E34: j[;tPj; | F34: 39 | N34: علم التجويد
B35: 3 | C35: 87 | D35: cUJg; ghi\ | E35: cUJg; ghi\ | F35: 41 | N35: اللغة الأردية
B36: 3 | C36: 91 | D36: ju;[{kJy; Fu;Md; | E36: ju;[{kJy; Fu;Md; | F36: 41 | N36: ترجمة القرآن
B37: 4 | C37: 4 | D37: my;Fu;Md; kddk; | E37: my;Fu;Md; kddk; | F37: 39 | N37: تحفيظ القرآن
B38: 4 | C38: 8 | D38: jg;]Pu; | E38: jg;]Pu; | F38: 39 | N38: علم التفسير
B39: 4 | C39: 12 | D39: c]{Yj; jg;]Pu; | E39: c]{Yj; jg;]Pu; | F39: 39 | N39: علم أصول التفسير
B40: 4 | C40: 18 | D40: `jP]; | E40: `jP]; | F40: 46 | N40: علم الحديث الشريف
B41: 4 | C41: 22 | D41: c]{Yy; `jP]; | E41: c]{Yy; `jP]; | F41: 46 | N41: علم أصول الحديث
...
